Workbook

Sheet Sheet1
C2: Accessibility Results | D2: 30 Min APW | E2: 45 Min APW | F2: 60 Min APW | G2: Net 30 | H2: Net 45 | I2: Net 60 | J2: KM Track | K2: Cost $B | L2: Cost $B Cheap | M2: Cost Expensive | N2: Avg Access/Cost | O2: Rank | Q2: Land Value Uplift Results | R2: 30 Min Lin. | S2: 45 Min Lin. | T2: 60 Min Lin. | U2: 30 Min Log | V2: 45 Min Log | W2: 60 Min Log | X2: BCR Lin | Y2: BCR LOG | Z2: BCR LIN Cheap | AA2: BCR LOG Cheap | AB2: BCR LIN Exp | AC2: BCR LOG Exp | AD2: BCR Average | AG2: Rank
C3: Base | D3: 42229 | E3: 175828 | F3: 441170 | Q3: Base | R3: 42229 | S3: 175828 | T3: 441170
C4: Bradfield Vaucluse | D4: 42583 | E4: 178426 | F4: 444122 | G4: =D4-$D$3 -> 354 | H4: =E4-$E$3 -> 2598 | I4: =F4-$F$3 -> 2952 | J4: 4.5 | K4: =J4*1.19 -> 5.355 | L4: =J4*0.632 -> 2.844 | M4: =J4*1.3 -> 5.85 | N4: =AVERAGE(G4:I4)/K4 -> 367.507 | O4: =RANK(N4,$N$4:$N$28) -> 12 | Q4: Bradfield Vaucluse | R4: 4306.4229 | S4: 14193.624 | T4: 8548.3621 | U4: 16251.917 | V4: 39663.604 | W4: 7849.0561 | X4: =AVERAGE(R4:T4)/(K4*1000) -> 1.6836856 | Y4: =AVERAGE(U4:W4)/(K4*1000) -> 3.9691613 | Z4: =AVERAGE(R4:T4)/(L4*1000) -> 3.1702308 | AA4: =AVERAGE(U4:W4)/(L4*1000) -> 7.4735791 | AB4: =AVERAGE(R4:T4)/(M4*1000) -> 1.5412199 | AC4: =AVERAGE(U4:W4)/(M4*1000) -> 3.6333092 | AD4: =AVERAGE(X4:AC4) -> 3.578531 | AG4: =RANK(AD4,$AD$4:$AD$28) -> 1
C5: Bradfield Sydenham | D5: 43468 | E5: 181495 | F5: 448502 | G5: =D5-$D$3 -> 1239 | H5: =E5-$E$3 -> 5667 | I5: =F5-$F$3 -> 7332 | J5: 10.5 | K5: =J5*1.19 -> 12.495 | L5: =J5*0.632 -> 6.636 | M5: =J5*1.3 -> 13.65 | N5: =AVERAGE(G5:I5)/K5 -> 379.83193 | O5: =RANK(N5,$N$4:$N$28) -> 11 | Q5: Bradfield Sydenham | R5: 12362.585 | S5: 23163.024 | T5: 16072.922 | U5: 5160.3246 | V5: 6719.6266 | W5: 3789.2358 | X5: =AVERAGE(R5:T5)/(K5*1000) -> 1.3765114 | Y5: =AVERAGE(U5:W5)/(K5*1000) -> 0.41801219 | Z5: =AVERAGE(R5:T5)/(L5*1000) -> 2.5918491 | AA5: =AVERAGE(U5:W5)/(L5*1000) -> 0.78707992 | AB5: =AVERAGE(R5:T5)/(M5*1000) -> 1.2600374 | AC5: =AVERAGE(U5:W5)/(M5*1000) -> 0.38264193 | AD5: =AVERAGE(X5:AC5) -> 1.136022 | AG5: =RANK(AD5,$AD$4:$AD$28) -> 14
C6: Bradfield Malabar | D6: 43288 | E6: 182143 | F6: 449317 | G6: =D6-$D$3 -> 1059 | H6: =E6-$E$3 -> 6315 | I6: =F6-$F$3 -> 8147 | J6: 11.1 | K6: =J6*1.19 -> 13.209 | L6: =J6*0.632 -> 7.0152 | M6: =J6*1.3 -> 14.43 | N6: =AVERAGE(G6:I6)/K6 -> 391.67739 | O6: =RANK(N6,$N$4:$N$28) -> 9 | Q6: Bradfield Malabar | R6: 14671.504 | S6: 33767.455 | T6: 23107.683 | U6: 8617.5906 | V6: 15046.535 | W6: 6611.0444 | X6: =AVERAGE(R6:T6)/(K6*1000) -> 1.8055024 | Y6: =AVERAGE(U6:W6)/(K6*1000) -> 0.76400358 | Z6: =AVERAGE(R6:T6)/(L6*1000) -> 3.399601 | AA6: =AVERAGE(U6:W6)/(L6*1000) -> 1.438551 | AB6: =AVERAGE(R6:T6)/(M6*1000) -> 1.6527291 | AC6: =AVERAGE(U6:W6)/(M6*1000) -> 0.69935712 | AD6: =AVERAGE(X6:AC6) -> 1.626624 | AG6: =RANK(AD6,$AD$4:$AD$28) -> 11
C7: Bradfield Sydenham & Malabar | D7: 43249 | E7: 181016 | F7: 448195.26 | G7: =D7-$D$3 -> 1020 | H7: =E7-$E$3 -> 5188 | I7: =F7-$F$3 -> 7025.259 | J7: =J6+J5 -> 21.6 | K7: =J7*1.19 -> 25.704 | L7: =J7*0.632 -> 13.6512 | M7: =J7*1.3 -> 28.08 | N7: =AVERAGE(G7:I7)/K7 -> 171.61089 | O7: =RANK(N7,$N$4:$N$28) -> 19 | Q7: Bradfield Sydenham & Malabar | R7: 17724.865 | S7: 29281.7 | T7: 19371.475 | U7: 8487.6473 | V7: 8868.1969 | W7: 5116.1825 | X7: =AVERAGE(R7:T7)/(K7*1000) -> 0.86080038 | Y7: =AVERAGE(U7:W7)/(K7*1000) -> 0.29142062 | Z7: =AVERAGE(R7:T7)/(L7*1000) -> 1.6208108 | AA7: =AVERAGE(U7:W7)/(L7*1000) -> 0.5487192 | AB7: =AVERAGE(R7:T7)/(M7*1000) -> 0.78796343 | AC7: =AVERAGE(U7:W7)/(M7*1000) -> 0.26676195 | AD7: =AVERAGE(X7:AC7) -> 0.72941274 | AG7: =RANK(AD7,$AD$4:$AD$28) -> 19
C8: Marginal Malabar | D8: =D7-D5 -> -219 | E8: =E7-E5 -> -479 | F8: =F7-F5 -> -306.74098 | G8: =D8 -> -219 | H8: =E8 -> -479 | I8: =F8 -> -306.74098 | J8: =J7-J5 -> 11.1 | K8: =J8*1.19 -> 13.209 | L8: =J8*0.632 -> 7.0152 | M8: =J8*1.3 -> 14.43 | N8: =AVERAGE(G8:I8)/K8 -> -25.35496 | O8: =RANK(N8,$N$4:$N$28) -> 23 | Q8: Marginal Malabar | R8: =R7-R5 -> 5362.2794 | S8: =S7-S5 -> 6118.6756 | T8: =T7-T5 -> 3298.553 | U8: =U7-U5 -> 3327.3227 | V8: =V7-V5 -> 2148.5703 | W8: =W7-W5 -> 1326.9467 | X8: =AVERAGE(R8:T8)/(K8*1000) -> 0.3729656 | Y8: =AVERAGE(U8:W8)/(K8*1000) -> 0.17167183 | Z8: =AVERAGE(R8:T8)/(L8*1000) -> 0.70226118 | AA8: =AVERAGE(U8:W8)/(L8*1000) -> 0.32324285 | AB8: =AVERAGE(R8:T8)/(M8*1000) -> 0.34140698 | AC8: =AVERAGE(U8:W8)/(M8*1000) -> 0.15714575 | AD8: =AVERAGE(X8:AC8) -> 0.34478237 | AG8: =RANK(AD8,$AD$4:$AD$28) -> 23
C9: Bradfield Full | D9: 42938 | E9: 181332 | F9: 448770 | G9: =D9-$D$3 -> 709 | H9: =E9-$E$3 -> 5504 | I9: =F9-$F$3 -> 7600 | J9: =J6+J5+J4 -> 26.1 | K9: =J9*1.19 -> 31.059 | L9: =J9*0.632 -> 16.4952 | M9: =J9*1.3 -> 33.93 | N9: =AVERAGE(G9:I9)/K9 -> 148.24474 | O9: =RANK(N9,$N$4:$N$28) -> 21 | Q9: Bradfield Full | R9: 9457.2782 | S9: 28202.394 | T9: 21152.844 | U9: 9220.2977 | V9: 32304.406 | W9: 10677.682 | X9: =AVERAGE(R9:T9)/(K9*1000) -> 0.63119136 | Y9: =AVERAGE(U9:W9)/(K9*1000) -> 0.5602497 | Z9: =AVERAGE(R9:T9)/(L9*1000) -> 1.1884774 | AA9: =AVERAGE(U9:W9)/(L9*1000) -> 1.0549005 | AB9: =AVERAGE(R9:T9)/(M9*1000) -> 0.57778286 | AC9: =AVERAGE(U9:W9)/(M9*1000) -> 0.51284395 | AD9: =AVERAGE(X9:AC9) -> 0.75424097 | AG9: =RANK(AD9,$AD$4:$AD$28) -> 18
C10: Marginal Full | D10: =D9-D7 -> -311 | E10: =E9-E7 -> 316 | F10: =F9-F7 -> 574.74098 | G10: =D10 -> -311 | H10: =E10 -> 316 | I10: =F10 -> 574.74098 | J10: =J9-J7 -> 4.5 | K10: =J10*1.19 -> 5.355 | L10: =J10*0.632 -> 2.844 | M10: =J10*1.3 -> 5.85 | N10: =AVERAGE(G10:I10)/K10 -> 36.087207 | O10: =RANK(N10,$N$4:$N$28) -> 22 | Q10: Marginal Full | R10: =R9-R7 -> -8267.5866 | S10: =S9-S7 -> -1079.3054 | T10: =T9-T7 -> 1781.3698 | U10: =U9-U7 -> 732.65041 | V10: =V9-V7 -> 23436.209 | W10: =W9-W7 -> 5561.4999 | X10: =AVERAGE(R10:T10)/(K10*1000) -> -0.47093198 | Y10: =AVERAGE(U10:W10)/(K10*1000) -> 1.8506293 | Z10: =AVERAGE(R10:T10)/(L10*1000) -> -0.88672319 | AA10: =AVERAGE(U10:W10)/(L10*1000) -> 3.4845709 | AB10: =AVERAGE(R10:T10)/(M10*1000) -> -0.43108389 | AC10: =AVERAGE(U10:W10)/(M10*1000) -> 1.6940376 | AD10: =AVERAGE(X10:AC10) -> 0.87341646 | AG10: =RANK(AD10,$AD$4:$AD$28) -> 16
C11: 1974 | D11: 42726 | E11: 178109 | F11: 443829 | G11: =D11-$D$3 -> 497 | H11: =E11-$E$3 -> 2281 | I11: =F11-$F$3 -> 2659 | J11: 4.53 | K11: =J11*1.19 -> 5.3907 | L11: =J11*0.632 -> 2.86296 | M11: =J11*1.3 -> 5.889 | N11: =AVERAGE(G11:I11)/K11 -> 336.19629 | O11: =RANK(N11,$N$4:$N$28) -> 13 | Q11: 1974 | R11: 5742.2911 | S11: 10835.134 | T11: 6968.6141 | U11: 3209.7953 | V11: 3117.5193 | W11: 1745.3826 | X11: =AVERAGE(R11:T11)/(K11*1000) -> 1.4559667 | Y11: =AVERAGE(U11:W11)/(K11*1000) -> 0.49917433 | Z11: =AVERAGE(R11:T11)/(L11*1000) -> 2.7414563 | AA11: =AVERAGE(U11:W11)/(L11*1000) -> 0.93990104 | AB11: =AVERAGE(R11:T11)/(M11*1000) -> 1.3327695 | AC11: =AVERAGE(U11:W11)/(M11*1000) -> 0.4569365 | AD11: =AVERAGE(X11:AC11) -> 1.2377007 | AG11: =RANK(AD11,$AD$4:$AD$28) -> 13
C12: 2001 | D12: 42515 | E12: 177614 | F12: 443145 | G12: =D12-$D$3 -> 286 | H12: =E12-$E$3 -> 1786 | I12: =F12-$F$3 -> 1975 | J12: 2.7 | K12: =J12*1.19 -> 3.213 | L12: =J12*0.632 -> 1.7064 | M12: =J12*1.3 -> 3.51 | N12: =AVERAGE(G12:I12)/K12 -> 419.85683 | O12: =RANK(N12,$N$4:$N$28) -> 6 | Q12: 2001 | R12: 3271.6911 | S12: 7403.3092 | T12: 4699.5995 | U12: 6171.008 | V12: 10264.327 | W12: 2603.5688 | X12: =AVERAGE(R12:T12)/(K12*1000) -> 1.595041 | Y12: =AVERAGE(U12:W12)/(K12*1000) -> 1.975195 | Z12: =AVERAGE(R12:T12)/(L12*1000) -> 3.0033208 | AA12: =AVERAGE(U12:W12)/(L12*1000) -> 3.7191171 | AB12: =AVERAGE(R12:T12)/(M12*1000) -> 1.460076 | AC12: =AVERAGE(U12:W12)/(M12*1000) -> 1.8080631 | AD12: =AVERAGE(X12:AC12) -> 2.2601355 | AG12: =RANK(AD12,$AD$4:$AD$28) -> 9
C13: 2056 Stage 1 | D13: 44755 | E13: 182509 | F13: 449850.32 | G13: =D13-$D$3 -> 2526 | H13: =E13-$E$3 -> 6681 | I13: =F13-$F$3 -> 8680.3175 | J13: 15.5 | K13: =J13*1.19 -> 18.445 | L13: =J13*0.632 -> 9.796 | M13: =J13*1.3 -> 20.15 | N13: =AVERAGE(G13:I13)/K13 -> 323.25504 | O13: =RANK(N13,$N$4:$N$28) -> 14 | Q13: 2056 Stage 1 | R13: 34207.86 | S13: 40288.478 | T13: 27042.995 | U13: 8891.706 | V13: 16811.084 | W13: 6037.0875 | X13: =AVERAGE(R13:T13)/(K13*1000) -> 1.8349929 | Y13: =AVERAGE(U13:W13)/(K13*1000) -> 0.57359496 | Z13: =AVERAGE(R13:T13)/(L13*1000) -> 3.4551291 | AA13: =AVERAGE(U13:W13)/(L13*1000) -> 1.0800285 | AB13: =AVERAGE(R13:T13)/(M13*1000) -> 1.6797243 | AC13: =AVERAGE(U13:W13)/(M13*1000) -> 0.52506 | AD13: =AVERAGE(X13:AC13) -> 1.524755 | AG13: =RANK(AD13,$AD$4:$AD$28) -> 12
C14: 2056 Stage 1 and 2 | D14: 45121.819 | E14: 184921.69 | F14: 453131.31 | G14: =D14-$D$3 -> 2892.8185 | H14: =E14-$E$3 -> 9093.6906 | I14: =F14-$F$3 -> 11961.31 | J14: =J13+11.3 -> 26.8 | K14: =J14*1.19 -> 31.892 | L14: =J14*0.632 -> 16.9376 | M14: =J14*1.3 -> 34.84 | N14: =AVERAGE(G14:I14)/K14 -> 250.30122 | O14: =RANK(N14,$N$4:$N$28) -> 15 | Q14: 2056 Stage 1 and 2 | R14: 39198.431 | S14: 51750.444 | T14: 35999.004 | U14: 12564.212 | V14: 21791.397 | W14: 8141.2006 | X14: =AVERAGE(R14:T14)/(K14*1000) -> 1.3268519 | Y14: =AVERAGE(U14:W14)/(K14*1000) -> 0.44417419 | Z14: =AVERAGE(R14:T14)/(L14*1000) -> 2.4983445 | AA14: =AVERAGE(U14:W14)/(L14*1000) -> 0.83634064 | AB14: =AVERAGE(R14:T14)/(M14*1000) -> 1.2145798 | AC14: =AVERAGE(U14:W14)/(M14*1000) -> 0.40659022 | AD14: =AVERAGE(X14:AC14) -> 1.1211469 | AG14: =RANK(AD14,$AD$4:$AD$28) -> 15
C15: Marginal Stage 2 Metro | D15: =D14-D13 -> 366.81852 | E15: =E14-E13 -> 2412.6906 | F15: =F14-F13 -> 3280.9928 | G15: =D15 -> 366.81852 | H15: =E15 -> 2412.6906 | I15: =F15 -> 3280.9928 | J15: =J14-J13 -> 11.3 | K15: =J15*1.19 -> 13.447 | L15: =J15*0.632 -> 7.1416 | M15: =J15*1.3 -> 14.69 | N15: =AVERAGE(G15:I15)/K15 -> 150.23182 | O15: =RANK(N15,$N$4:$N$28) -> 20 | Q15: Marginal Stage 2 Metro | R15: =R14-R13 -> 4990.5712 | S15: =S14-S13 -> 11461.967 | T15: =T14-T13 -> 8956.0091 | U15: =U14-U13 -> 3672.5062 | V15: =V14-V13 -> 4980.3135 | W15: =W14-W13 -> 2104.1131 | X15: =AVERAGE(R15:T15)/(K15*1000) -> 0.62984425 | Y15: =AVERAGE(U15:W15)/(K15*1000) -> 0.26665013 | Z15: =AVERAGE(R15:T15)/(L15*1000) -> 1.1859409 | AA15: =AVERAGE(U15:W15)/(L15*1000) -> 0.50207857 | AB15: =AVERAGE(R15:T15)/(M15*1000) -> 0.57654974 | AC15: =AVERAGE(U15:W15)/(M15*1000) -> 0.24408743 | AD15: =AVERAGE(X15:AC15) -> 0.56752517 | AG15: =RANK(AD15,$AD$4:$AD$28) -> 21
C16: Light Rail Extension | D16: 42253.305 | E16: 176295.36 | F16: 442053.4 | G16: =D16-$D$3 -> 24.305499 | H16: =E16-$E$3 -> 467.35502 | I16: =F16-F$3 -> 883.39921 | J16: 10 | K16: =J16*0.25 -> 2.5 | N16: =AVERAGE(G16:I16)/K16 -> 183.3413 | O16: =RANK(N16,$N$4:$N$28) -> 18 | Q16: Light Rail Extension | R16: 320.04394 | S16: 1973.4398 | T16: 2336.228 | U16: 442.98121 | V16: 1089.5878 | W16: 737.57403 | X16: =AVERAGE(R16:T16)/(K16*1000) -> 0.6172949 | Y16: =AVERAGE(U16:W16)/(K16*1000) -> 0.30268574 | Z16: - | AA16: - | AB16: - | AC16: - | AD16: =AVERAGE(X16:Y16) -> 0.45999032 | AG16: =RANK(AD16,$AD$4:$AD$28) -> 22
C17: Light Rail with Oxford Street Rail | D17: 42458.685 | E17: 177020.42 | F17: 442606.46 | G17: =D17-$D$3 -> 229.68494 | H17: =E17-$E$3 -> 1192.4174 | I17: =F17-F$3 -> 1436.464 | J17: 18.8 | K17: =J17*0.25 -> 4.7 | N17: =AVERAGE(G17:I17)/K17 -> 202.7352 | O17: =RANK(N17,$N$4:$N$28) -> 17 | Q17: Light Rail with Oxford Street Rail | R17: 2338.5019 | S17: 5091.2033 | T17: 3684.8744 | U17: 1466.9749 | V17: 3731.1304 | W17: 1364.0094 | X17: =AVERAGE(R17:T17)/(K17*1000) -> 0.78826805 | Y17: =AVERAGE(U17:W17)/(K17*1000) -> 0.4653982 | Z17: - | AA17: - | AB17: - | AC17: - | AD17: =AVERAGE(X17:Y17) -> 0.62683313 | AG17: =RANK(AD17,$AD$4:$AD$28) -> 20
C18: Marginal Oxford Street | D18: =D17-D16 -> 205.37944 | E18: =E17-E16 -> 725.06239 | F18: =F17-F16 -> 553.0648 | G18: =D18 -> 205.37944 | H18: =E18 -> 725.06239 | I18: =F18 -> 553.0648 | J18: =J17-J16 -> 8.8 | K18: =K17-K16 -> 2.2 | N18: =AVERAGE(G18:I18)/K18 -> 224.77373 | O18: =RANK(N18,$N$4:$N$28) -> 16 | Q18: Marginal Oxford Street | R18: =R17-R16 -> 2018.458 | S18: =S17-S16 -> 3117.7635 | T18: =T17-T16 -> 1348.6464 | U18: =U17-U16 -> 1023.9936 | V18: =V17-V16 -> 2641.5426 | W18: =W17-W16 -> 626.43535 | X18: =AVERAGE(R18:T18)/(K18*1000) -> 0.98255572 | Y18: =AVERAGE(U18:W18)/(K18*1000) -> 0.65029872 | Z18: - | AA18: - | AB18: - | AC18: - | AD18: =AVERAGE(X18:Y18) -> 0.81642722 | AG18: =RANK(AD18,$AD$4:$AD$28) -> 17
C19: Extensive Eastern Suburbs Lightrail | D19: 46954.927 | E19: 183765.39 | F19: 449459.53 | G19: =D19-D3 -> 4725.9268 | H19: =E19-E3 -> 7937.3854 | I19: =F19-F3 -> 8289.533 | J19: =11.57+J17+7.59+3.31+1.16+3.72+1.14+15.37+5.03 -> 67.69 | K19: =J19*0.25 -> 16.9225 | N19: =AVERAGE(G19:I19)/K19 -> 412.72163 | O19: =RANK(N19,$N$4:$N$28) -> 7 | Q19: Extensive Eastern Suburbs Lightrail | R19: 60395.953 | S19: 45544.6 | T19: 27860.18 | U19: 30907.972 | V19: 24416.747 | W19: 10866.092 | X19: =AVERAGE(R19:T19)/(K19*1000) -> 2.6355588 | Y19: =AVERAGE(U19:W19)/(K19*1000) -> 1.3038028 | Z19: - | AA19: - | AB19: - | AC19: - | AD19: =AVERAGE(X19:Y19) -> 1.9696808 | AG19: =RANK(AD19,$AD$4:$AD$28) -> 10
C20: Marginal Extensive Lightrail | D20: =D19-D17 -> 4496.2419 | E20: =E19-E17 -> 6744.968 | F20: =F19-F17 -> 6853.069 | G20: =D20 -> 4496.2419 | H20: =E20 -> 6744.968 | I20: =F20 -> 6853.069 | J20: =J19-J17 -> 48.89 | K20: =K19-K17 -> 12.2225 | N20: =AVERAGE(G20:I20)/K20 -> 493.46912 | O20: =RANK(N20,$N$4:$N$28) -> 5 | Q20: Marginal Extensive Lightrail | R20: =R19-R17 -> 58057.451 | S20: =S19-S17 -> 40453.397 | T20: =T19-T17 -> 24175.306 | U20: =U19-U17 -> 29440.997 | V20: =V19-V17 -> 20685.617 | W20: =W19-W17 -> 9502.0823 | X20: =AVERAGE(R20:T20)/(K20*1000) -> 3.34591 | Y20: =AVERAGE(U20:W20)/(K20*1000) -> 1.6262002 | Z20: - | AA20: - | AB20: - | AC20: - | AD20: =AVERAGE(X20:Y20) -> 2.4860551 | AG20: =RANK(AD20,$AD$4:$AD$28) -> 4
C21: Mills Proposal | D21: 43336 | E21: 182521.86 | F21: 449840.61 | G21: =D21-$D$3 -> 1107 | H21: =E21-$E$3 -> 6693.862 | I21: =F21-F3 -> 8670.6094 | J21: 8.97 | K21: =J21*1.19 -> 10.6743 | L21: =J21*0.632 -> 5.66904 | M21: =J21*1.3 -> 11.661 | N21: =AVERAGE(G21:I21)/K21 -> 514.36539 | O21: =RANK(N21,$N$4:$N$28) -> 3 | Q21: Mills Proposal | R21: 13740.942 | S21: 36311.043 | T21: 25220.706 | U21: 17468.359 | V21: 16311.381 | W21: 7129.7067 | X21: =AVERAGE(R21:T21)/(K21*1000) -> 2.3505895 | Y21: =AVERAGE(U21:W21)/(K21*1000) -> 1.277506 | Z21: =AVERAGE(R21:T21)/(L21*1000) -> 4.4259517 | AA21: =AVERAGE(U21:W21)/(L21*1000) -> 2.4054306 | AB21: =AVERAGE(R21:T21)/(M21*1000) -> 2.1516934 | AC21: =AVERAGE(U21:W21)/(M21*1000) -> 1.1694093 | AD21: =AVERAGE(X21:AC21) -> 2.2967634 | AG21: =RANK(AD21,$AD$4:$AD$28) -> 8
C22: Mills Proposal Metro | D22: 43719 | E22: 183170 | F22: 449184.5 | G22: =D22-$D$3 -> 1490 | H22: =E22-$E$3 -> 7342 | I22: =F22-F3 -> 8014.5026 | J22: 8.97 | K22: =J22*1.19+0.08*6.83 -> 11.2207 | L22: =J22*0.632+0.08*6.83 -> 6.21544 | M22: =J22*1.3+0.08*6.83 -> 12.2074 | N22: =AVERAGE(G22:I22)/K22 -> 500.45905 | O22: =RANK(N22,$N$4:$N$28) -> 4 | Q22: Mills Proposal Metro | R22: 18425.425 | S22: 38021.81 | T22: 22749.715 | U22: 18501.995 | V22: 26023.517 | W22: 8811.6447 | X22: =AVERAGE(R22:T22)/(K22*1000) -> 2.3527038 | Y22: =AVERAGE(U22:W22)/(K22*1000) -> 1.5844869 | Z22: =AVERAGE(R22:T22)/(L22*1000) -> 4.2473233 | AA22: =AVERAGE(U22:W22)/(L22*1000) -> 2.8604656 | AB22: =AVERAGE(R22:T22)/(M22*1000) -> 2.1625394 | AC22: =AVERAGE(U22:W22)/(M22*1000) -> 1.456416 | AD22: =AVERAGE(X22:AC22) -> 2.4439892 | AG22: =RANK(AD22,$AD$4:$AD$28) -> 6
C23: Alternative 2056 Metro | D23: 46138.937 | E23: 185488 | F23: 453575 | G23: =D23-$D$3 -> 3909.9368 | H23: =E23-$E$3 -> 9660 | I23: =F23-F3 -> 12405 | J23: 12.2 | K23: =J23*1.19 -> 14.518 | L23: =J23*0.632 -> 7.7104 | M23: =J23*1.3 -> 15.86 | N23: =AVERAGE(G23:I23)/K23 -> 596.38464 | O23: =RANK(N23,$N$4:$N$28) -> 1 | Q23: Alternative 2056 Metro | R23: 48766.592 | S23: 53315.931 | T23: 35500.493 | U23: 26691.733 | V23: 17955.284 | W23: 7730.1774 | X23: =AVERAGE(R23:T23)/(K23*1000) -> 3.1589065 | Y23: =AVERAGE(U23:W23)/(K23*1000) -> 1.2025806 | Z23: =AVERAGE(R23:T23)/(L23*1000) -> 5.9479411 | AA23: =AVERAGE(U23:W23)/(L23*1000) -> 2.2643526 | AB23: =AVERAGE(R23:T23)/(M23*1000) -> 2.8916145 | AC23: =AVERAGE(U23:W23)/(M23*1000) -> 1.1008237 | AD23: =AVERAGE(X23:AC23) -> 2.7610365 | AG23: =RANK(AD23,$AD$4:$AD$28) -> 2
C24: Alternative 2056 Metro + Coogeee | D24: 46182 | E24: 185789 | F24: 453801 | G24: =D24-$D$3 -> 3953 | H24: =E24-$E$3 -> 9961 | I24: =F24-F4 -> 9679 | J24: =12.2+2.36 -> 14.56 | K24: =12.2*1.19+2.36*0.25 -> 15.108 | L24: =12.2*0.632+2.36*0.25 -> 8.3004 | M24: =J24*1.3 -> 18.928 | N24: =AVERAGE(G24:I24)/K24 -> 520.54099 | O24: =RANK(N24,$N$4:$N$28) -> 2 | Q24: Alternative 2056 Metro + Coogee | R24: 49304.39 | S24: 54498.237 | T24: 35917.827 | U24: 27267.579 | V24: 18810.504 | W24: 7873.0551 | X24: =AVERAGE(R24:T24)/(K24*1000) -> 3.0827035 | Y24: =AVERAGE(U24:W24)/(K24*1000) -> 1.1903437 | Z24: =AVERAGE(R24:T24)/(L24*1000) -> 5.6109928 | AA24: =AVERAGE(U24:W24)/(L24*1000) -> 2.166608 | AB24: =AVERAGE(R24:T24)/(M24*1000) -> 2.4605603 | AC24: =AVERAGE(U24:W24)/(M24*1000) -> 0.95011162 | AD24: =AVERAGE(X24:AC24) -> 2.5768866 | AG24: =RANK(AD24,$AD$4:$AD$28) -> 3
D25: =D24-D23 -> 43.063239 | E25: =E24-E23 -> 301 | F25: =F24-F23 -> 226 | J25: =J24-J23 -> 2.36 | K25: =J25*0.25 -> 0.59 | L25: =J25*0.25 -> 0.59 | R25: =R24-R23 -> 537.79801 | S25: =S24-S23 -> 1182.306 | T25: =T24-T23 -> 417.33382 | U25: =U24-U23 -> 575.84674 | V25: =V24-V23 -> 855.22005 | W25: =W24-W23 -> 142.87771
C26: Alternative 2056 Metro + Maroubra | D26: 46186 | E26: 185848 | F26: 453859 | G26: =D26-$D$3 -> 3957 | H26: =E26-$E$3 -> 10020 | I26: =F26-F5 -> 5357 | J26: =12.2+4.74 -> 16.94 | K26: =12.2*1.19+4.74*0.25 -> 15.703 | L26: =12.2*0.632+4.74*0.25 -> 8.8954 | M26: =J26*1.3 -> 22.022 | N26: =AVERAGE(G26:I26)/K26 -> 410.4099 | O26: =RANK(N26,$N$4:$N$28) -> 8 | Q26: Alternative 2056 Metro + Maroubra | R26: 49822.341 | S26: 57243.685 | T26: 36784.981 | U26: 27830.974 | V26: 20207.119 | W26: 7966.284 | X26: =AVERAGE(R26:T26)/(K26*1000) -> 3.053578 | Y26: =AVERAGE(U26:W26)/(K26*1000) -> 1.1888254 | Z26: =AVERAGE(R26:T26)/(L26*1000) -> 5.3904642 | AA26: =AVERAGE(U26:W26)/(L26*1000) -> 2.0986269 | AB26: =AVERAGE(R26:T26)/(M26*1000) -> 2.1773833 | AC26: =AVERAGE(U26:W26)/(M26*1000) -> 0.84770346 | AD26: =AVERAGE(X26:AC26) -> 2.4594302 | AG26: =RANK(AD26,$AD$4:$AD$28) -> 5
J27: =J26-J23 -> 4.74 | K27: =J27*0.25 -> 1.185 | L27: =J27*0.25 -> 1.185 | R27: =R26-R23 -> 1055.7494 | S27: =S26-S23 -> 3927.7541 | T27: =T26-T23 -> 1284.4878 | U27: =U26-U23 -> 1139.2414 | V27: =V26-V23 -> 2251.8349 | W27: =W26-W23 -> 236.10658
C28: Alternative 2056 Metro + Coogee&Metro | D28: 46230 | E28: 186154 | F28: 454094 | G28: =D28-$D$3 -> 4001 | H28: =E28-$E$3 -> 10326 | I28: =F28-F6 -> 4777 | J28: =12.2+4.74+2.36 -> 19.3 | K28: =12.2*1.19+4.74*0.25+2.36*0.25 -> 16.293 | L28: =12.2*0.632+4.74*0.25+2.36*0.25 -> 9.4854 | M28: =J28*1.3 -> 25.09 | N28: =AVERAGE(G28:I28)/K28 -> 390.84269 | O28: =RANK(N28,$N$4:$N$28) -> 10 | Q28: Alternative 2056 Metro Maroubra + Coogee | R28: 50350.959 | S28: 58438.356 | T28: 37214.192 | U28: 28398.744 | V28: 21073.708 | W28: 8113.9177 | X28: =AVERAGE(R28:T28)/(K28*1000) -> 2.9870396 | Y28: =AVERAGE(U28:W28)/(K28*1000) -> 1.1781413 | Z28: =AVERAGE(R28:T28)/(L28*1000) -> 5.1308153 | AA28: =AVERAGE(U28:W28)/(L28*1000) -> 2.0236845 | AB28: =AVERAGE(R28:T28)/(M28*1000) -> 1.9397304 | AC28: =AVERAGE(U28:W28)/(M28*1000) -> 0.76506403 | AD28: =AVERAGE(X28:AC28) -> 2.3374125 | AG28: =RANK(AD28,$AD$4:$AD$28) -> 7
C29: Alternative 2056 Metro + Coogee&Metro | D29: =D28-D23 -> 91.063239 | E29: =E28-E23 -> 666 | F29: =F28-F23 -> 519 | G29: =D29-$D$3 -> -42137.937 | H29: =E29-$E$3 -> -175162 | I29: =F29-F7 -> -447676.26 | J29: =J28-J23 -> 7.1 | K29: =J29*0.25 -> 1.775 | L29: =J29*0.25 -> 1.775 | M29: =J29*1.3 -> 9.23 | N29: =AVERAGE(G29:I29)/K29 -> -124878.16 | O29: =RANK(N29,$N$4:$N$28) -> #N/A | R29: =R28-R23 -> 1584.3673 | S29: =S28-S23 -> 5122.4255 | T29: =T28-T23 -> 1713.6986 | U29: =U28-U23 -> 1707.0112 | V29: =V28-V23 -> 3118.4242 | W29: =W28-W23 -> 383.74035
Q31: Scenario | R31: 30 Min Lin. | S31: 45 Min Lin. | T31: 60 Min Lin. | U31: 30 Min Log | V31: 45 Min Log | W31: 60 Min Log | X31: Avg LVA | Y31: Cost Domestic | Z31: Cost International | AA31: BCR Domestic | AB31: BCR International | AC31: Rank | AD31: BCR Average Log | AF31: BCR Average Lin | AG31: Rank
Q32: Base | R32: 42229 | S32: 175828 | T32: 441170
K33: =PV(0.07,8,0,-K4,0) -> 3.1166588 | L33: =PV(0.07,8,0,-L4,0) -> 1.6552339 | M33: =PV(0.07,8,0,-M4,0) -> 3.4047533 | O33: DCR | Q33: Bradfield Vaucluse | R33: =PV($O$34,17,0,-R4,0) -> 1363.3032 | S33: =PV($O$34,17,0,-S4,0) -> 4493.338 | T33: =PV($O$34,17,0,-T4,0) -> 2706.1925 | U33: =PV($O$34,17,0,-U4,0) -> 5144.9408 | V33: =PV($O$34,17,0,-V4,0) -> 12556.481 | W33: =PV($O$34,17,0,-W4,0) -> 2484.8101 | X33: =AVERAGE(R33:W33) -> 4791.511 | Y33: =PV($O$34,8,0,-K4,0) -> 3.1166588 | Z33: =PV($O$34,8,0,-L4,0) -> 1.6552339 | AA33: =($X33/1000)/Y33 -> 1.5373871 | AB33: =($X33/1000)/Z33 -> 2.8947637 | AC33: =RANK(AA33,($AA$33:$AA$36,$AA$38,$AA$40:$AA$43,$AA$45:$AA$46,$AA$48,$AA$50:$AA$53,$AA$55,$AA$57),0) -> 1 | AD33: =AVERAGE(Y33,AC33) -> 2.0583294 | AE33: =AF33-AD33 -> 2395.1445 | AF33: =AVERAGE(X33,AB33) -> 2397.2029 | AG33: =RANK(AI33,$AI$33:$AI$57) -> #N/A | AI33: =AVERAGE(AD33,AF33) -> 1199.6306
K34: =PV(0.07,8,0,-K5,0) -> 7.2722038 | L34: =PV(0.07,8,0,-L5,0) -> 3.8622124 | M34: =PV(0.07,8,0,-M5,0) -> 7.9444243 | O34: 0.07 | Q34: Bradfield Sydenham | R34: =PV($O$34,17,0,-R5,0) -> 3913.6779 | S34: =PV($O$34,17,0,-S5,0) -> 7332.8203 | T34: =PV($O$34,17,0,-T5,0) -> 5088.2753 | U34: =PV($O$34,17,0,-U5,0) -> 1633.6266 | V34: =PV($O$34,17,0,-V5,0) -> 2127.2617 | W34: =PV($O$34,17,0,-W5,0) -> 1199.575 | X34: =AVERAGE(R34:W34) -> 3549.2061 | Y34: =PV($O$34,8,0,-K5,0) -> 7.2722038 | Z34: =PV($O$34,8,0,-L5,0) -> 3.8622124 | AA34: =(X34/1000)/Y34 -> 0.48805098 | AB34: =($X34/1000)/Z34 -> 0.91895674 | AC34: =RANK(AA34,($AA$33:$AA$36,$AA$38,$AA$40:$AA$43,$AA$45:$AA$46,$AA$48,$AA$50:$AA$53,$AA$55,$AA$57),0) -> 13 | AD34: =AVERAGE(Y34,AC34) -> 10.136102 | AE34: =AF34-AD34 -> 1764.9265 | AF34: =AVERAGE(X34,AB34) -> 1775.0626 | AG34: =RANK(AI34,$AI$33:$AI$57) -> #N/A | AI34: =AVERAGE(AD34,AF34) -> 892.59933
K35: =PV(0.07,8,0,-K6,0) -> 7.6877583 | L35: =PV(0.07,8,0,-L6,0) -> 4.0829103 | M35: =PV(0.07,8,0,-M6,0) -> 8.3983914 | Q35: Bradfield Malabar | R35: =PV($O$34,17,0,-R6,0) -> 4644.6225 | S35: =PV($O$34,17,0,-S6,0) -> 10689.911 | T35: =PV($O$34,17,0,-T6,0) -> 7315.3007 | U35: =PV($O$34,17,0,-U6,0) -> 2728.1085 | V35: =PV($O$34,17,0,-V6,0) -> 4763.3476 | W35: =PV($O$34,17,0,-W6,0) -> 2092.8873 | X35: =AVERAGE(R35:W35) -> 5372.363 | Y35: =PV($O$34,8,0,-K6,0) -> 7.6877583 | Z35: =PV($O$34,8,0,-L6,0) -> 4.0829103 | AA35: =(X35/1000)/Y35 -> 0.69882049 | AB35: =($X35/1000)/Z35 -> 1.3158171 | AC35: =RANK(AA35,($AA$33:$AA$36,$AA$38,$AA$40:$AA$43,$AA$45:$AA$46,$AA$48,$AA$50:$AA$53,$AA$55,$AA$57),0) -> 10 | AD35: =AVERAGE(Y35,AC35) -> 8.8438791 | AE35: =AF35-AD35 -> 2677.9955 | AF35: =AVERAGE(X35,AB35) -> 2686.8394 | AG35: =RANK(AI35,$AI$33:$AI$57) -> #N/A | AI35: =AVERAGE(AD35,AF35) -> 1347.8416
K36: =PV(0.07,8,0,-K7,0) -> 14.959962 | L36: =PV(0.07,8,0,-L7,0) -> 7.9451227 | M36: =PV(0.07,8,0,-M7,0) -> 16.342816 | Q36: Bradfield Sydenham & Malabar | R36: =PV($O$34,17,0,-R7,0) -> 5611.2383 | S36: =PV($O$34,17,0,-S7,0) -> 9269.8363 | T36: =PV($O$34,17,0,-T7,0) -> 6132.5127 | U36: =PV($O$34,17,0,-U7,0) -> 2686.9718 | V36: =PV($O$34,17,0,-V7,0) -> 2807.444 | W36: =PV($O$34,17,0,-W7,0) -> 1619.6524 | X36: =AVERAGE(R36:W36) -> 4687.9426 | Y36: =PV($O$34,8,0,-K7,0) -> 14.959962 | Z36: =PV($O$34,8,0,-L7,0) -> 7.9451227 | AA36: =(X36/1000)/Y36 -> 0.31336594 | AB36: =($X36/1000)/Z36 -> 0.5900403 | AC36: =RANK(AA36,($AA$33:$AA$36,$AA$38,$AA$40:$AA$43,$AA$45:$AA$46,$AA$48,$AA$50:$AA$53,$AA$55,$AA$57),0) -> 17 | AD36: =AVERAGE(Y36,AC36) -> 15.979981 | AE36: =AF36-AD36 -> 2328.2863 | AF36: =AVERAGE(X36,AB36) -> 2344.2663 | AG36: =RANK(AI36,$AI$33:$AI$57) -> #N/A | AI36: =AVERAGE(AD36,AF36) -> 1180.1231
K37: =PV(0.07,8,0,-K8,0) -> 7.6877583 | L37: =PV(0.07,8,0,-L8,0) -> 4.0829103 | M37: =PV(0.07,8,0,-M8,0) -> 8.3983914 | Q37: Marginal Malabar | R37: =PV($O$34,17,0,-R8,0) -> 1697.5603 | S37: =PV($O$34,17,0,-S8,0) -> 1937.016 | T37: =PV($O$34,17,0,-T8,0) -> 1044.2374 | U37: =PV($O$34,17,0,-U8,0) -> 1053.3452 | V37: =PV($O$34,17,0,-V8,0) -> 680.18234 | W37: =PV($O$34,17,0,-W8,0) -> 420.07733 | X37: =AVERAGE(R37:W37) -> 1138.7364 | Y37: =PV($O$34,8,0,-K8,0) -> 7.6877583 | Z37: =PV($O$34,8,0,-L8,0) -> 4.0829103 | AA37: =(X37/1000)/Y37 -> 0.14812334 | AB37: =($X37/1000)/Z37 -> 0.27890312 | AC37: =RANK(AA37,($AA$33:$AA$36,$AA$38,$AA$40:$AA$43,$AA$45:$AA$46,$AA$48,$AA$50:$AA$53,$AA$55,$AA$57),0) -> #N/A | AD37: =AVERAGE(Y37,AC37) -> #N/A | AE37: =AF37-AD37 -> #N/A | AF37: =AVERAGE(X37,AB37) -> 569.50767 | AG37: =RANK(AI37,$AI$33:$AI$57) -> #N/A | AI37: =AVERAGE(AD37,AF37) -> #N/A
K38: =PV(0.07,8,0,-K9,0) -> 18.076621 | L38: =PV(0.07,8,0,-L9,0) -> 9.6003566 | M38: =PV(0.07,8,0,-M9,0) -> 19.747569 | Q38: Bradfield Full | R38: =PV($O$34,17,0,-R9,0) -> 2993.9321 | S38: =PV($O$34,17,0,-S9,0) -> 8928.1558 | T38: =PV($O$34,17,0,-T9,0) -> 6696.4488 | U38: =PV($O$34,17,0,-U9,0) -> 2918.9101 | V38: =PV($O$34,17,0,-V9,0) -> 10226.748 | W38: =PV($O$34,17,0,-W9,0) -> 3380.2808 | X38: =AVERAGE(R38:W38) -> 5857.4125 | Y38: =PV($O$34,8,0,-K9,0) -> 18.076621 | Z38: =PV($O$34,8,0,-L9,0) -> 9.6003566 | AA38: =(X38/1000)/Y38 -> 0.3240325 | AB38: =($X38/1000)/Z38 -> 0.61012448 | AC38: =RANK(AA38,($AA$33:$AA$36,$AA$38,$AA$40:$AA$43,$AA$45:$AA$46,$AA$48,$AA$50:$AA$53,$AA$55,$AA$57),0) -> 16 | AD38: =AVERAGE(Y38,AC38) -> 17.03831 | AE38: =AF38-AD38 -> 2911.973 | AF38: =AVERAGE(X38,AB38) -> 2929.0113 | AG38: =RANK(AI38,$AI$33:$AI$57) -> #N/A | AI38: =AVERAGE(AD38,AF38) -> 1473.0248
K39: =PV(0.07,8,0,-K10,0) -> 3.1166588 | L39: =PV(0.07,8,0,-L10,0) -> 1.6552339 | M39: =PV(0.07,8,0,-M10,0) -> 3.4047533 | Q39: Marginal Full | R39: =PV($O$34,17,0,-R10,0) -> -2617.3062 | S39: =PV($O$34,17,0,-S10,0) -> -341.68045 | T39: =PV($O$34,17,0,-T10,0) -> 563.93606 | U39: =PV($O$34,17,0,-U10,0) -> 231.93836 | V39: =PV($O$34,17,0,-V10,0) -> 7419.3036 | W39: =PV($O$34,17,0,-W10,0) -> 1760.6284 | X39: =AVERAGE(R39:W39) -> 1169.47 | Y39: =PV($O$34,8,0,-K10,0) -> 3.1166588 | Z39: =PV($O$34,8,0,-L10,0) -> 1.6552339 | AA39: =(X39/1000)/Y39 -> 0.37523196 | AB39: =($X39/1000)/Z39 -> 0.70652853 | AC39: =RANK(AA39,($AA$33:$AA$36,$AA$38,$AA$40:$AA$43,$AA$45:$AA$46,$AA$48,$AA$50:$AA$53,$AA$55,$AA$57),0) -> #N/A | AD39: =AVERAGE(Y39,AC39) -> #N/A | AE39: =AF39-AD39 -> #N/A | AF39: =AVERAGE(X39,AB39) -> 585.08825 | AG39: =RANK(AI39,$AI$33:$AI$57) -> #N/A | AI39: =AVERAGE(AD39,AF39) -> #N/A
K40: =PV(0.07,8,0,-K11,0) -> 3.1374365 | L40: =PV(0.07,8,0,-L11,0) -> 1.6662688 | M40: =PV(0.07,8,0,-M11,0) -> 3.4274516 | Q40: 1974 | R40: =PV($O$34,17,0,-R11,0) -> 1817.8623 | S40: =PV($O$34,17,0,-S11,0) -> 3430.126 | T40: =PV($O$34,17,0,-T11,0) -> 2206.0848 | U40: =PV($O$34,17,0,-U11,0) -> 1016.139 | V40: =PV($O$34,17,0,-V11,0) -> 986.92677 | W40: =PV($O$34,17,0,-W11,0) -> 552.54343 | X40: =AVERAGE(R40:W40) -> 1668.2804 | Y40: =PV($O$34,8,0,-K11,0) -> 3.1374365 | Z40: =PV($O$34,8,0,-L11,0) -> 1.6662688 | AA40: =(X40/1000)/Y40 -> 0.5317336 | AB40: =($X40/1000)/Z40 -> 1.0012072 | AC40: =RANK(AA40,($AA$33:$AA$36,$AA$38,$AA$40:$AA$43,$AA$45:$AA$46,$AA$48,$AA$50:$AA$53,$AA$55,$AA$57),0) -> 12 | AD40: =AVERAGE(Y40,AC40) -> 7.5687182 | AE40: =AF40-AD40 -> 827.07208 | AF40: =AVERAGE(X40,AB40) -> 834.6408 | AG40: =RANK(AI40,$AI$33:$AI$57) -> #N/A | AI40: =AVERAGE(AD40,AF40) -> 421.10476
K41: =PV(0.07,8,0,-K12,0) -> 1.8699953 | L41: =PV(0.07,8,0,-L12,0) -> 0.99314034 | M41: =PV(0.07,8,0,-M12,0) -> 2.042852 | Q41: 2001 | R41: =PV($O$34,17,0,-R12,0) -> 1035.7336 | S41: =PV($O$34,17,0,-S12,0) -> 2343.6981 | T41: =PV($O$34,17,0,-T12,0) -> 1487.7728 | U41: =PV($O$34,17,0,-U12,0) -> 1953.5831 | V41: =PV($O$34,17,0,-V12,0) -> 3249.4232 | W41: =PV($O$34,17,0,-W12,0) -> 824.2232 | X41: =AVERAGE(R41:W41) -> 1815.739 | Y41: =PV($O$34,8,0,-K12,0) -> 1.8699953 | Z41: =PV($O$34,8,0,-L12,0) -> 0.99314034 | AA41: =(X41/1000)/Y41 -> 0.97098589 | AB41: =($X41/1000)/Z41 -> 1.8282804 | AC41: =RANK(AA41,($AA$33:$AA$36,$AA$38,$AA$40:$AA$43,$AA$45:$AA$46,$AA$48,$AA$50:$AA$53,$AA$55,$AA$57),0) -> 9 | AD41: =AVERAGE(Y41,AC41) -> 5.4349976 | AE41: =AF41-AD41 -> 903.34865 | AF41: =AVERAGE(X41,AB41) -> 908.78364 | AG41: =RANK(AI41,$AI$33:$AI$57) -> #N/A | AI41: =AVERAGE(AD41,AF41) -> 457.10932
K42: =PV(0.07,8,0,-K13,0) -> 10.735158 | L42: =PV(0.07,8,0,-L13,0) -> 5.7013612 | M42: =PV(0.07,8,0,-M13,0) -> 11.727483 | Q42: 2056 Stage 1 | R42: =PV($O$34,17,0,-R13,0) -> 10829.332 | S42: =PV($O$34,17,0,-S13,0) -> 12754.3 | T42: =PV($O$34,17,0,-T13,0) -> 8561.1197 | U42: =PV($O$34,17,0,-U13,0) -> 2814.8864 | V42: =PV($O$34,17,0,-V13,0) -> 5321.9585 | W42: =PV($O$34,17,0,-W13,0) -> 1911.1873 | X42: =AVERAGE(R42:W42) -> 7032.1308 | Y42: =PV($O$34,8,0,-K13,0) -> 10.735158 | Z42: =PV($O$34,8,0,-L13,0) -> 5.7013612 | AA42: =(X42/1000)/Y42 -> 0.65505611 | AB42: =($X42/1000)/Z42 -> 1.2334126 | AC42: =RANK(AA42,($AA$33:$AA$36,$AA$38,$AA$40:$AA$43,$AA$45:$AA$46,$AA$48,$AA$50:$AA$53,$AA$55,$AA$57),0) -> 11 | AD42: =AVERAGE(Y42,AC42) -> 10.867579 | AE42: =AF42-AD42 -> 3505.8145 | AF42: =AVERAGE(X42,AB42) -> 3516.6821 | AG42: =RANK(AI42,$AI$33:$AI$57) -> #N/A | AI42: =AVERAGE(AD42,AF42) -> 1763.7748
...

Sheet Sheet2
I1: AVG | J1: Costs | K1: Int | L1: BCR | M1: Int
C2: 48766.592 | D2: 53315.931 | E2: 35500.493 | F2: 26691.733 | G2: 17955.284 | H2: 7730.1774 | P2: 13740.942 | Q2: 36311.043 | R2: 25220.706 | S2: 17468.359 | T2: 16311.381 | U2: 7129.7067 | AB2: 60395.953 | AC2: 45544.6 | AD2: 27860.18 | AE2: 30907.972 | AF2: 24416.747 | AG2: 10866.092
C3: =PV(Sheet1!$R81,17,0,-Sheet2!C$2) -> 41177.412 | D3: =PV(Sheet1!$R81,17,0,-Sheet2!D$2) -> 45018.772 | E3: =PV(Sheet1!$R81,17,0,-Sheet2!E$2) -> 29975.817 | F3: =PV(Sheet1!$R81,17,0,-Sheet2!F$2) -> 22537.898 | G3: =PV(Sheet1!$R81,17,0,-Sheet2!G$2) -> 15161.037 | H3: =PV(Sheet1!$R81,17,0,-Sheet2!H$2) -> 6527.1878 | I3: =AVERAGE(C3:H3) -> 26733.021 | J3: =PV(Sheet1!$R81,8,0,-Sheet1!K$23,0) -> 13.407129 | K3: =PV(Sheet1!$R81,8,0,-Sheet1!L$23,0) -> 7.120425 | L3: =($I3/1000)/J3 -> 1.9939407 | M3: =($I3/1000)/K3 -> 3.7544136 | P3: =PV(Sheet1!$R81,17,0,-Sheet2!P$2) -> 11602.542 | Q3: =PV(Sheet1!$R81,17,0,-Sheet2!Q$2) -> 30660.227 | R3: =PV(Sheet1!$R81,17,0,-Sheet2!R$2) -> 21295.796 | S3: =PV(Sheet1!$R81,17,0,-Sheet2!S$2) -> 14749.889 | T3: =PV(Sheet1!$R81,17,0,-Sheet2!T$2) -> 13772.962 | U3: =PV(Sheet1!$R81,17,0,-Sheet2!U$2) -> 6020.1638 | V3: =AVERAGE(P3:U3) -> 16350.264 | W3: =PV(Sheet1!$R81,8,0,-Sheet1!K$21,0) -> 9.857537 | X3: =PV(Sheet1!$R81,8,0,-Sheet1!L$21,0) -> 5.2352633 | Y3: =($V3/1000)/W3 -> 1.6586561 | Z3: =($V3/1000)/X3 -> 3.1231024 | AB3: =PV(Sheet1!$R81,17,0,-Sheet2!AB$2) -> 50996.983 | AC3: =PV(Sheet1!$R81,17,0,-Sheet2!AC$2) -> 38456.835 | AD3: =PV(Sheet1!$R81,17,0,-Sheet2!AD$2) -> 23524.509 | AE3: =PV(Sheet1!$R81,17,0,-Sheet2!AE$2) -> 26097.996 | AF3: =PV(Sheet1!$R81,17,0,-Sheet2!AF$2) -> 20616.952 | AG3: =PV(Sheet1!$R81,17,0,-Sheet2!AG$2) -> 9175.0832 | AH3: =AVERAGE(AB3:AG3) -> 28144.726 | AI3: =PV(Sheet1!$R81,8,0,-Sheet1!K$19,0) -> 15.627645 | AJ3: =($AH3/1000)/AI3 -> 1.8009576
C4: =PV(Sheet1!$R82,17,0,-Sheet2!C$2) -> 34827.274 | D4: =PV(Sheet1!$R82,17,0,-Sheet2!D$2) -> 38076.242 | E4: =PV(Sheet1!$R82,17,0,-Sheet2!E$2) -> 25353.123 | F4: =PV(Sheet1!$R82,17,0,-Sheet2!F$2) -> 19062.236 | G4: =PV(Sheet1!$R82,17,0,-Sheet2!G$2) -> 12822.992 | H4: =PV(Sheet1!$R82,17,0,-Sheet2!H$2) -> 5520.6033 | I4: =AVERAGE(C4:H4) -> 22610.412 | J4: =PV(Sheet1!R82,8,0,-Sheet1!K$23,0) -> 12.390973 | K4: =PV(Sheet1!$R82,8,0,-Sheet1!L$23,0) -> 6.5807522 | L4: =($I4/1000)/J4 -> 1.8247487 | M4: =($I4/1000)/K4 -> 3.43584 | P4: =PV(Sheet1!$R82,17,0,-Sheet2!P$2) -> 9813.2665 | Q4: =PV(Sheet1!$R82,17,0,-Sheet2!Q$2) -> 25931.987 | R4: =PV(Sheet1!$R82,17,0,-Sheet2!R$2) -> 18011.684 | S4: =PV(Sheet1!$R82,17,0,-Sheet2!S$2) -> 12475.248 | T4: =PV(Sheet1!$R82,17,0,-Sheet2!T$2) -> 11648.977 | U4: =PV(Sheet1!$R82,17,0,-Sheet2!U$2) -> 5091.7696 | V4: =AVERAGE(P4:U4) -> 13828.822 | W4: =PV(Sheet1!$R82,8,0,-Sheet1!K$21,0) -> 9.1104123 | X4: =PV(Sheet1!$R82,8,0,-Sheet1!L$21,0) -> 4.8384711 | Y4: =($V4/1000)/W4 -> 1.517914 | Z4: =($V4/1000)/X4 -> 2.8580975 | AB4: =PV(Sheet1!$R82,17,0,-Sheet2!AB$2) -> 43132.529 | AC4: =PV(Sheet1!$R82,17,0,-Sheet2!AC$2) -> 32526.248 | AD4: =PV(Sheet1!$R82,17,0,-Sheet2!AD$2) -> 19896.698 | AE4: =PV(Sheet1!$R82,17,0,-Sheet2!AE$2) -> 22073.316 | AF4: =PV(Sheet1!$R82,17,0,-Sheet2!AF$2) -> 17437.527 | AG4: =PV(Sheet1!$R82,17,0,-Sheet2!AG$2) -> 7760.1559 | AH4: =AVERAGE(AB4:AG4) -> 23804.412 | AI4: =PV(Sheet1!$R82,8,0,-Sheet1!K$19,0) -> 14.443191 | AJ4: =($AH4/1000)/AI4 -> 1.6481408
C5: =PV(Sheet1!$R83,17,0,-Sheet2!C$2) -> 29504.59 | D5: =PV(Sheet1!$R83,17,0,-Sheet2!D$2) -> 32257.015 | E5: =PV(Sheet1!$R83,17,0,-Sheet2!E$2) -> 21478.382 | F5: =PV(Sheet1!$R83,17,0,-Sheet2!F$2) -> 16148.937 | G5: =PV(Sheet1!$R83,17,0,-Sheet2!G$2) -> 10863.242 | H5: =PV(Sheet1!$R83,17,0,-Sheet2!H$2) -> 4676.8845 | I5: =AVERAGE(C5:H5) -> 19154.842 | J5: =PV(Sheet1!R83,8,0,-Sheet1!K$23,0) -> 11.460643 | K5: =PV(Sheet1!$R83,8,0,-Sheet1!L$23,0) -> 6.086661 | L5: =($I5/1000)/J5 -> 1.6713583 | M5: =($I5/1000)/K5 -> 3.1470197 | P5: =PV(Sheet1!$R83,17,0,-Sheet2!P$2) -> 8313.496 | Q5: =PV(Sheet1!$R83,17,0,-Sheet2!Q$2) -> 21968.778 | R5: =PV(Sheet1!$R83,17,0,-Sheet2!R$2) -> 15258.942 | S5: =PV(Sheet1!$R83,17,0,-Sheet2!S$2) -> 10568.645 | T5: =PV(Sheet1!$R83,17,0,-Sheet2!T$2) -> 9868.6535 | U5: =PV(Sheet1!$R83,17,0,-Sheet2!U$2) -> 4313.5898 | V5: =AVERAGE(P5:U5) -> 11715.351 | W5: =PV(Sheet1!$R83,8,0,-Sheet1!K$21,0) -> 8.426391 | X5: =PV(Sheet1!$R83,8,0,-Sheet1!L$21,0) -> 4.4751925 | Y5: =($V5/1000)/W5 -> 1.3903165 | Z5: =($V5/1000)/X5 -> 2.6178428 | AB5: =PV(Sheet1!$R83,17,0,-Sheet2!AB$2) -> 36540.545 | AC5: =PV(Sheet1!$R83,17,0,-Sheet2!AC$2) -> 27555.232 | AD5: =PV(Sheet1!$R83,17,0,-Sheet2!AD$2) -> 16855.867 | AE5: =PV(Sheet1!$R83,17,0,-Sheet2!AE$2) -> 18699.831 | AF5: =PV(Sheet1!$R83,17,0,-Sheet2!AF$2) -> 14772.534 | AG5: =PV(Sheet1!$R83,17,0,-Sheet2!AG$2) -> 6574.1642 | AH5: =AVERAGE(AB5:AG5) -> 20166.362 | AI5: =PV(Sheet1!$R83,8,0,-Sheet1!K$19,0) -> 13.358778 | AJ5: =($AH5/1000)/AI5 -> 1.5095964
C6: =PV(Sheet1!$R84,17,0,-Sheet2!C$2) -> 25035.464 | D6: =PV(Sheet1!$R84,17,0,-Sheet2!D$2) -> 27370.972 | E6: =PV(Sheet1!$R84,17,0,-Sheet2!E$2) -> 18225.003 | F6: =PV(Sheet1!$R84,17,0,-Sheet2!F$2) -> 13702.821 | G6: =PV(Sheet1!$R84,17,0,-Sheet2!G$2) -> 9217.7624 | H6: =PV(Sheet1!$R84,17,0,-Sheet2!H$2) -> 3968.4663 | I6: =AVERAGE(C6:H6) -> 16253.415 | J6: =PV(Sheet1!R84,8,0,-Sheet1!K$23,0) -> 10.60816 | K6: =PV(Sheet1!$R84,8,0,-Sheet1!L$23,0) -> 5.6339138 | L6: =($I6/1000)/J6 -> 1.5321615 | M6: =($I6/1000)/K6 -> 2.8849243 | P6: =PV(Sheet1!$R84,17,0,-Sheet2!P$2) -> 7054.2321 | Q6: =PV(Sheet1!$R84,17,0,-Sheet2!Q$2) -> 18641.118 | R6: =PV(Sheet1!$R84,17,0,-Sheet2!R$2) -> 12947.636 | S6: =PV(Sheet1!$R84,17,0,-Sheet2!S$2) -> 8967.7883 | T6: =PV(Sheet1!$R84,17,0,-Sheet2!T$2) -> 8373.8264 | U6: =PV(Sheet1!$R84,17,0,-Sheet2!U$2) -> 3660.2007 | V6: =AVERAGE(P6:U6) -> 9940.8002 | W6: =PV(Sheet1!$R84,8,0,-Sheet1!K$21,0) -> 7.7996065 | X6: =PV(Sheet1!$R84,8,0,-Sheet1!L$21,0) -> 4.142312 | Y6: =($V6/1000)/W6 -> 1.2745259 | Z6: =($V6/1000)/X6 -> 2.3998193 | AB6: =PV(Sheet1!$R84,17,0,-Sheet2!AB$2) -> 31005.666 | AC6: =PV(Sheet1!$R84,17,0,-Sheet2!AC$2) -> 23381.379 | AD6: =PV(Sheet1!$R84,17,0,-Sheet2!AD$2) -> 14302.671 | AE6: =PV(Sheet1!$R84,17,0,-Sheet2!AE$2) -> 15867.326 | AF6: =PV(Sheet1!$R84,17,0,-Sheet2!AF$2) -> 12534.905 | AG6: =PV(Sheet1!$R84,17,0,-Sheet2!AG$2) -> 5578.3608 | AH6: =AVERAGE(AB6:AG6) -> 17111.718 | AI6: =PV(Sheet1!$R84,8,0,-Sheet1!K$19,0) -> 12.365105 | AJ6: =($AH6/1000)/AI6 -> 1.3838716
C7: =PV(Sheet1!$R85,17,0,-Sheet2!C$2) -> 21276.702 | D7: =PV(Sheet1!$R85,17,0,-Sheet2!D$2) -> 23261.564 | E7: =PV(Sheet1!$R85,17,0,-Sheet2!E$2) -> 15488.747 | F7: =PV(Sheet1!$R85,17,0,-Sheet2!F$2) -> 11645.514 | G7: =PV(Sheet1!$R85,17,0,-Sheet2!G$2) -> 7833.8309 | H7: =PV(Sheet1!$R85,17,0,-Sheet2!H$2) -> 3372.6508 | I7: =AVERAGE(C7:H7) -> 13813.168 | J7: =PV(Sheet1!R85,8,0,-Sheet1!K$23,0) -> 9.8263539 | K7: =PV(Sheet1!$R85,8,0,-Sheet1!L$23,0) -> 5.2187022 | L7: =($I7/1000)/J7 -> 1.4057267 | M7: =($I7/1000)/K7 -> 2.6468589 | P7: =PV(Sheet1!$R85,17,0,-Sheet2!P$2) -> 5995.1276 | Q7: =PV(Sheet1!$R85,17,0,-Sheet2!Q$2) -> 15842.388 | R7: =PV(Sheet1!$R85,17,0,-Sheet2!R$2) -> 11003.711 | S7: =PV(Sheet1!$R85,17,0,-Sheet2!S$2) -> 7621.3873 | T7: =PV(Sheet1!$R85,17,0,-Sheet2!T$2) -> 7116.6013 | U7: =PV(Sheet1!$R85,17,0,-Sheet2!U$2) -> 3110.6674 | V7: =AVERAGE(P7:U7) -> 8448.3136 | W7: =PV(Sheet1!$R85,8,0,-Sheet1!K$21,0) -> 7.2247864 | X7: =PV(Sheet1!$R85,8,0,-Sheet1!L$21,0) -> 3.8370294 | Y7: =($V7/1000)/W7 -> 1.1693513 | Z7: =($V7/1000)/X7 -> 2.201785 | AB7: =PV(Sheet1!$R85,17,0,-Sheet2!AB$2) -> 26350.554 | AC7: =PV(Sheet1!$R85,17,0,-Sheet2!AC$2) -> 19870.958 | AD7: =PV(Sheet1!$R85,17,0,-Sheet2!AD$2) -> 12155.304 | AE7: =PV(Sheet1!$R85,17,0,-Sheet2!AE$2) -> 13485.046 | AF7: =PV(Sheet1!$R85,17,0,-Sheet2!AF$2) -> 10652.946 | AG7: =PV(Sheet1!$R85,17,0,-Sheet2!AG$2) -> 4740.8398 | AH7: =AVERAGE(AB7:AG7) -> 14542.608 | AI7: =PV(Sheet1!$R85,8,0,-Sheet1!K$19,0) -> 11.453814 | AJ7: =($AH7/1000)/AI7 -> 1.2696738
C8: =PV(Sheet1!$R86,17,0,-Sheet2!C$2) -> 18110.177 | D8: =PV(Sheet1!$R86,17,0,-Sheet2!D$2) -> 19799.64 | E8: =PV(Sheet1!$R86,17,0,-Sheet2!E$2) -> 13183.62 | F8: =PV(Sheet1!$R86,17,0,-Sheet2!F$2) -> 9912.3597 | G8: =PV(Sheet1!$R86,17,0,-Sheet2!G$2) -> 6667.9536 | H8: =PV(Sheet1!$R86,17,0,-Sheet2!H$2) -> 2870.7128 | I8: =AVERAGE(C8:H8) -> 11757.41 | J8: =PV(Sheet1!R86,8,0,-Sheet1!K$23,0) -> 9.1087728 | K8: =PV(Sheet1!$R86,8,0,-Sheet1!L$23,0) -> 4.8376003 | L8: =($I8/1000)/J8 -> 1.2907788 | M8: =($I8/1000)/K8 -> 2.430422 | P8: =PV(Sheet1!$R86,17,0,-Sheet2!P$2) -> 5102.897 | Q8: =PV(Sheet1!$R86,17,0,-Sheet2!Q$2) -> 13484.629 | R8: =PV(Sheet1!$R86,17,0,-Sheet2!R$2) -> 9366.0728 | S8: =PV(Sheet1!$R86,17,0,-Sheet2!S$2) -> 6487.1271 | T8: =PV(Sheet1!$R86,17,0,-Sheet2!T$2) -> 6057.4663 | U8: =PV(Sheet1!$R86,17,0,-Sheet2!U$2) -> 2647.7194 | V8: =AVERAGE(P8:U8) -> 7190.9853 | W8: =PV(Sheet1!$R86,8,0,-Sheet1!K$21,0) -> 6.6971879 | X8: =PV(Sheet1!$R86,8,0,-Sheet1!L$21,0) -> 3.5568258 | Y8: =($V8/1000)/W8 -> 1.0737321 | Z8: =($V8/1000)/X8 -> 2.0217423 | AB8: =PV(Sheet1!$R86,17,0,-Sheet2!AB$2) -> 22428.908 | AC8: =PV(Sheet1!$R86,17,0,-Sheet2!AC$2) -> 16913.644 | AD8: =PV(Sheet1!$R86,17,0,-Sheet2!AD$2) -> 10346.28 | AE8: =PV(Sheet1!$R86,17,0,-Sheet2!AE$2) -> 11478.121 | AF8: =PV(Sheet1!$R86,17,0,-Sheet2!AF$2) -> 9067.5112 | AG8: =PV(Sheet1!$R86,17,0,-Sheet2!AG$2) -> 4035.2798 | AH8: =AVERAGE(AB8:AG8) -> 12378.291 | AI8: =PV(Sheet1!$R86,8,0,-Sheet1!K$19,0) -> 10.617386 | AJ8: =($AH8/1000)/AI8 -> 1.1658511
C9: =PV(Sheet1!$R87,17,0,-Sheet2!C$2) -> 15438.254 | D9: =PV(Sheet1!$R87,17,0,-Sheet2!D$2) -> 16878.458 | E9: =PV(Sheet1!$R87,17,0,-Sheet2!E$2) -> 11238.547 | F9: =PV(Sheet1!$R87,17,0,-Sheet2!F$2) -> 8449.919 | G9: =PV(Sheet1!$R87,17,0,-Sheet2!G$2) -> 5684.183 | H9: =PV(Sheet1!$R87,17,0,-Sheet2!H$2) -> 2447.1762 | I9: =AVERAGE(C9:H9) -> 10022.756 | J9: =PV(Sheet1!R87,8,0,-Sheet1!K$23,0) -> 8.4496082 | K9: =PV(Sheet1!$R87,8,0,-Sheet1!L$23,0) -> 4.487523 | L9: =($I9/1000)/J9 -> 1.18618 | M9: =($I9/1000)/K9 -> 2.2334718 | P9: =PV(Sheet1!$R87,17,0,-Sheet2!P$2) -> 4350.0304 | Q9: =PV(Sheet1!$R87,17,0,-Sheet2!Q$2) -> 11495.146 | R9: =PV(Sheet1!$R87,17,0,-Sheet2!R$2) -> 7984.2296 | S9: =PV(Sheet1!$R87,17,0,-Sheet2!S$2) -> 5530.0352 | T9: =PV(Sheet1!$R87,17,0,-Sheet2!T$2) -> 5163.7653 | U9: =PV(Sheet1!$R87,17,0,-Sheet2!U$2) -> 2257.0825 | V9: =AVERAGE(P9:U9) -> 6130.0482 | W9: =PV(Sheet1!$R87,8,0,-Sheet1!K$21,0) -> 6.2125398 | X9: =PV(Sheet1!$R87,8,0,-Sheet1!L$21,0) -> 3.2994329 | Y9: =($V9/1000)/W9 -> 0.98672177 | Z9: =($V9/1000)/X9 -> 1.8579097 | AB9: =PV(Sheet1!$R87,17,0,-Sheet2!AB$2) -> 19119.812 | AC9: =PV(Sheet1!$R87,17,0,-Sheet2!AC$2) -> 14418.254 | AD9: =PV(Sheet1!$R87,17,0,-Sheet2!AD$2) -> 8819.8196 | AE9: =PV(Sheet1!$R87,17,0,-Sheet2!AE$2) -> 9784.6724 | AF9: =PV(Sheet1!$R87,17,0,-Sheet2!AF$2) -> 7729.7169 | AG9: =PV(Sheet1!$R87,17,0,-Sheet2!AG$2) -> 3439.9264 | AH9: =AVERAGE(AB9:AG9) -> 10552.034 | AI9: =PV(Sheet1!$R87,8,0,-Sheet1!K$19,0) -> 9.8490491 | AJ9: =($AH9/1000)/AI9 -> 1.0713759
C10: =PV(Sheet1!$R88,17,0,-Sheet2!C$2) -> 13180.096 | D10: =PV(Sheet1!$R88,17,0,-Sheet2!D$2) -> 14409.641 | E10: =PV(Sheet1!$R88,17,0,-Sheet2!E$2) -> 9594.681 | F10: =PV(Sheet1!$R88,17,0,-Sheet2!F$2) -> 7213.9466 | G10: =PV(Sheet1!$R88,17,0,-Sheet2!G$2) -> 4852.7557 | H10: =PV(Sheet1!$R88,17,0,-Sheet2!H$2) -> 2089.2269 | I10: =AVERAGE(C10:H10) -> 8556.7244 | J10: =PV(Sheet1!R88,8,0,-Sheet1!K$23,0) -> 7.8436237 | K10: =PV(Sheet1!$R88,8,0,-Sheet1!L$23,0) -> 4.1656892 | L10: =($I10/1000)/J10 -> 1.0909147 | M10: =($I10/1000)/K10 -> 2.0540957 | P10: =PV(Sheet1!$R88,17,0,-Sheet2!P$2) -> 3713.75 | Q10: =PV(Sheet1!$R88,17,0,-Sheet2!Q$2) -> 9813.7475 | R10: =PV(Sheet1!$R88,17,0,-Sheet2!R$2) -> 6816.3738 | S10: =PV(Sheet1!$R88,17,0,-Sheet2!S$2) -> 4721.1551 | T10: =PV(Sheet1!$R88,17,0,-Sheet2!T$2) -> 4408.4597 | U10: =PV(Sheet1!$R88,17,0,-Sheet2!U$2) -> 1926.9383 | V10: =AVERAGE(P10:U10) -> 5233.4041 | W10: =PV(Sheet1!$R88,8,0,-Sheet1!K$21,0) -> 5.7669922 | X10: =PV(Sheet1!$R88,8,0,-Sheet1!L$21,0) -> 3.0628059 | Y10: =($V10/1000)/W10 -> 0.9074755 | Z10: =($V10/1000)/X10 -> 1.708696 | AB10: =PV(Sheet1!$R88,17,0,-Sheet2!AB$2) -> 16323.151 | AC10: =PV(Sheet1!$R88,17,0,-Sheet2!AC$2) -> 12309.291 | AD10: =PV(Sheet1!$R88,17,0,-Sheet2!AD$2) -> 7529.7417 | AE10: =PV(Sheet1!$R88,17,0,-Sheet2!AE$2) -> 8353.4652 | AF10: =PV(Sheet1!$R88,17,0,-Sheet2!AF$2) -> 6599.0887 | AG10: =PV(Sheet1!$R88,17,0,-Sheet2!AG$2) -> 2936.7672 | AH10: =AVERAGE(AB10:AG10) -> 9008.5842 | AI10: =PV(Sheet1!$R88,8,0,-Sheet1!K$19,0) -> 9.1427002 | AJ10: =($AH10/1000)/AI10 -> 0.98533081
C11: =PV(Sheet1!$R89,17,0,-Sheet2!C$2) -> 11268.651 | D11: =PV(Sheet1!$R89,17,0,-Sheet2!D$2) -> 12319.882 | E11: =PV(Sheet1!$R89,17,0,-Sheet2!E$2) -> 8203.2117 | F11: =PV(Sheet1!$R89,17,0,-Sheet2!F$2) -> 6167.7434 | G11: =PV(Sheet1!$R89,17,0,-Sheet2!G$2) -> 4148.9845 | H11: =PV(Sheet1!$R89,17,0,-Sheet2!H$2) -> 1786.2366 | I11: =AVERAGE(C11:H11) -> 7315.7848 | J11: =PV(Sheet1!R89,8,0,-Sheet1!K$23,0) -> 7.2860946 | K11: =PV(Sheet1!$R89,8,0,-Sheet1!L$23,0) -> 3.8695898 | L11: =($I11/1000)/J11 -> 1.0040749 | M11: =($I11/1000)/K11 -> 1.8905841 | P11: =PV(Sheet1!$R89,17,0,-Sheet2!P$2) -> 3175.1632 | Q11: =PV(Sheet1!$R89,17,0,-Sheet2!Q$2) -> 8390.508 | R11: =PV(Sheet1!$R89,17,0,-Sheet2!R$2) -> 5827.8287 | S11: =PV(Sheet1!$R89,17,0,-Sheet2!S$2) -> 4036.4693 | T11: =PV(Sheet1!$R89,17,0,-Sheet2!T$2) -> 3769.1225 | U11: =PV(Sheet1!$R89,17,0,-Sheet2!U$2) -> 1647.484 | V11: =AVERAGE(P11:U11) -> 4474.4293 | W11: =PV(Sheet1!$R89,8,0,-Sheet1!K$21,0) -> 5.3570712 | X11: =PV(Sheet1!$R89,8,0,-Sheet1!L$21,0) -> 2.8451 | Y11: =($V11/1000)/W11 -> 0.83523796 | Z11: =($V11/1000)/X11 -> 1.5726791 | AB11: =PV(Sheet1!$R89,17,0,-Sheet2!AB$2) -> 13955.885 | AC11: =PV(Sheet1!$R89,17,0,-Sheet2!AC$2) -> 10524.135 | AD11: =PV(Sheet1!$R89,17,0,-Sheet2!AD$2) -> 6437.7403 | AE11: =PV(Sheet1!$R89,17,0,-Sheet2!AE$2) -> 7142.0033 | AF11: =PV(Sheet1!$R89,17,0,-Sheet2!AF$2) -> 5642.0554 | AG11: =PV(Sheet1!$R89,17,0,-Sheet2!AG$2) -> 2510.8623 | AH11: =AVERAGE(AB11:AG11) -> 7702.1136 | AI11: =PV(Sheet1!$R89,8,0,-Sheet1!K$19,0) -> 8.4928321 | AJ11: =($AH11/1000)/AI11 -> 0.90689578
C12: =PV(Sheet1!$R90,17,0,-Sheet2!C$2) -> 9648.2102 | D12: =PV(Sheet1!$R90,17,0,-Sheet2!D$2) -> 10548.273 | E12: =PV(Sheet1!$R90,17,0,-Sheet2!E$2) -> 7023.5833 | F12: =PV(Sheet1!$R90,17,0,-Sheet2!F$2) -> 5280.817 | G12: =PV(Sheet1!$R90,17,0,-Sheet2!G$2) -> 3552.3572 | H12: =PV(Sheet1!$R90,17,0,-Sheet2!H$2) -> 1529.3744 | I12: =AVERAGE(C12:H12) -> 6263.7691 | J12: =PV(Sheet1!R90,8,0,-Sheet1!K$23,0) -> 6.7727541 | K12: =PV(Sheet1!$R90,8,0,-Sheet1!L$23,0) -> 3.5969585 | L12: =($I12/1000)/J12 -> 0.92484815 | M12: =($I12/1000)/K12 -> 1.7414071 | P12: =PV(Sheet1!$R90,17,0,-Sheet2!P$2) -> 2718.5722 | Q12: =PV(Sheet1!$R90,17,0,-Sheet2!Q$2) -> 7183.9463 | R12: =PV(Sheet1!$R90,17,0,-Sheet2!R$2) -> 4989.7822 | S12: =PV(Sheet1!$R90,17,0,-Sheet2!S$2) -> 3456.0217 | T12: =PV(Sheet1!$R90,17,0,-Sheet2!T$2) -> 3227.1197 | U12: =PV(Sheet1!$R90,17,0,-Sheet2!U$2) -> 1410.5745 | V12: =AVERAGE(P12:U12) -> 3831.0028 | W12: =PV(Sheet1!$R90,8,0,-Sheet1!K$21,0) -> 4.9796397 | X12: =PV(Sheet1!$R90,8,0,-Sheet1!L$21,0) -> 2.644649 | Y12: =($V12/1000)/W12 -> 0.76933332 | Z12: =($V12/1000)/X12 -> 1.4485865 | AB12: =PV(Sheet1!$R90,17,0,-Sheet2!AB$2) -> 11949.017 | AC12: =PV(Sheet1!$R90,17,0,-Sheet2!AC$2) -> 9010.7563 | AD12: =PV(Sheet1!$R90,17,0,-Sheet2!AD$2) -> 5511.9881 | AE12: =PV(Sheet1!$R90,17,0,-Sheet2!AE$2) -> 6114.9775 | AF12: =PV(Sheet1!$R90,17,0,-Sheet2!AF$2) -> 4830.7233 | AG12: =PV(Sheet1!$R90,17,0,-Sheet2!AG$2) -> 2149.7983 | AH12: =AVERAGE(AB12:AG12) -> 6594.5435 | AI12: =PV(Sheet1!$R90,8,0,-Sheet1!K$19,0) -> 7.8944711 | AJ12: =($AH12/1000)/AI12 -> 0.83533695
C13: =PV(Sheet1!$R91,17,0,-Sheet2!C$2) -> 8272.4046 | D13: =PV(Sheet1!$R91,17,0,-Sheet2!D$2) -> 9044.1208 | E13: =PV(Sheet1!$R91,17,0,-Sheet2!E$2) -> 6022.0415 | F13: =PV(Sheet1!$R91,17,0,-Sheet2!F$2) -> 4527.7884 | G13: =PV(Sheet1!$R91,17,0,-Sheet2!G$2) -> 3045.8018 | H13: =PV(Sheet1!$R91,17,0,-Sheet2!H$2) -> 1311.2902 | I13: =AVERAGE(C13:H13) -> 5370.5746 | J13: =PV(Sheet1!R91,8,0,-Sheet1!K$23,0) -> 6.2997449 | K13: =PV(Sheet1!$R91,8,0,-Sheet1!L$23,0) -> 3.3457469 | L13: =($I13/1000)/J13 -> 0.85250668 | M13: =($I13/1000)/K13 -> 1.6051945 | P13: =PV(Sheet1!$R91,17,0,-Sheet2!P$2) -> 2330.912 | Q13: =PV(Sheet1!$R91,17,0,-Sheet2!Q$2) -> 6159.5372 | R13: =PV(Sheet1!$R91,17,0,-Sheet2!R$2) -> 4278.2544 | S13: =PV(Sheet1!$R91,17,0,-Sheet2!S$2) -> 2963.2035 | T13: =PV(Sheet1!$R91,17,0,-Sheet2!T$2) -> 2766.9422 | U13: =PV(Sheet1!$R91,17,0,-Sheet2!U$2) -> 1209.4308 | V13: =AVERAGE(P13:U13) -> 3284.7133 | W13: =PV(Sheet1!$R91,8,0,-Sheet1!K$21,0) -> 4.6318616 | X13: =PV(Sheet1!$R91,8,0,-Sheet1!L$21,0) -> 2.4599467 | Y13: =($V13/1000)/W13 -> 0.70915619 | Z13: =($V13/1000)/X13 -> 1.3352783 | AB13: =PV(Sheet1!$R91,17,0,-Sheet2!AB$2) -> 10245.124 | AC13: =PV(Sheet1!$R91,17,0,-Sheet2!AC$2) -> 7725.8497 | AD13: =PV(Sheet1!$R91,17,0,-Sheet2!AD$2) -> 4725.9953 | AE13: =PV(Sheet1!$R91,17,0,-Sheet2!AE$2) -> 5243.0001 | AF13: =PV(Sheet1!$R91,17,0,-Sheet2!AF$2) -> 4141.8768 | AG13: =PV(Sheet1!$R91,17,0,-Sheet2!AG$2) -> 1843.2436 | AH13: =AVERAGE(AB13:AG13) -> 5654.1815 | AI13: =PV(Sheet1!$R91,8,0,-Sheet1!K$19,0) -> 7.3431211 | AJ13: =($AH13/1000)/AI13 -> 0.76999703
C14: =PV(Sheet1!$R92,17,0,-Sheet2!C$2) -> 7102.5781 | D14: =PV(Sheet1!$R92,17,0,-Sheet2!D$2) -> 7765.1636 | E14: =PV(Sheet1!$R92,17,0,-Sheet2!E$2) -> 5170.4459 | F14: =PV(Sheet1!$R92,17,0,-Sheet2!F$2) -> 3887.4998 | G14: =PV(Sheet1!$R92,17,0,-Sheet2!G$2) -> 2615.0855 | H14: =PV(Sheet1!$R92,17,0,-Sheet2!H$2) -> 1125.8566 | I14: =AVERAGE(C14:H14) -> 4611.1049 | J14: =PV(Sheet1!R92,8,0,-Sheet1!K$23,0) -> 5.8635767 | K14: =PV(Sheet1!$R92,8,0,-Sheet1!L$23,0) -> 3.1141012 | L14: =($I14/1000)/J14 -> 0.78639799 | M14: =($I14/1000)/K14 -> 1.4807177 | P14: =PV(Sheet1!$R92,17,0,-Sheet2!P$2) -> 2001.2905 | Q14: =PV(Sheet1!$R92,17,0,-Sheet2!Q$2) -> 5288.4979 | R14: =PV(Sheet1!$R92,17,0,-Sheet2!R$2) -> 3673.2531 | S14: =PV(Sheet1!$R92,17,0,-Sheet2!S$2) -> 2544.1677 | T14: =PV(Sheet1!$R92,17,0,-Sheet2!T$2) -> 2375.6603 | U14: =PV(Sheet1!$R92,17,0,-Sheet2!U$2) -> 1038.4014 | V14: =AVERAGE(P14:U14) -> 2820.2118 | W14: =PV(Sheet1!$R92,8,0,-Sheet1!K$21,0) -> 4.3111707 | X14: =PV(Sheet1!$R92,8,0,-Sheet1!L$21,0) -> 2.2896302 | Y14: =($V14/1000)/W14 -> 0.65416379 | Z14: =($V14/1000)/X14 -> 1.2317325 | AB14: =PV(Sheet1!$R92,17,0,-Sheet2!AB$2) -> 8796.3288 | AC14: =PV(Sheet1!$R92,17,0,-Sheet2!AC$2) -> 6633.3133 | AD14: =PV(Sheet1!$R92,17,0,-Sheet2!AD$2) -> 4057.6776 | AE14: =PV(Sheet1!$R92,17,0,-Sheet2!AE$2) -> 4501.5712 | AF14: =PV(Sheet1!$R92,17,0,-Sheet2!AF$2) -> 3556.1611 | AG14: =PV(Sheet1!$R92,17,0,-Sheet2!AG$2) -> 1582.5848 | AH14: =AVERAGE(AB14:AG14) -> 4854.6061 | AI14: =PV(Sheet1!$R92,8,0,-Sheet1!K$19,0) -> 6.8347139 | AJ14: =($AH14/1000)/AI14 -> 0.71028666
C15: =PV(Sheet1!$R93,17,0,-Sheet2!C$2) -> 6106.4508 | D15: =PV(Sheet1!$R93,17,0,-Sheet2!D$2) -> 6676.1096 | E15: =PV(Sheet1!$R93,17,0,-Sheet2!E$2) -> 4445.2976 | F15: =PV(Sheet1!$R93,17,0,-Sheet2!F$2) -> 3342.283 | G15: =PV(Sheet1!$R93,17,0,-Sheet2!G$2) -> 2248.3232 | H15: =PV(Sheet1!$R93,17,0,-Sheet2!H$2) -> 967.95668 | I15: =AVERAGE(C15:H15) -> 3964.4035 | J15: =PV(Sheet1!R93,8,0,-Sheet1!K$23,0) -> 5.4610889 | K15: =PV(Sheet1!$R93,8,0,-Sheet1!L$23,0) -> 2.900343 | L15: =($I15/1000)/J15 -> 0.72593645 | M15: =($I15/1000)/K15 -> 1.366874 | P15: =PV(Sheet1!$R93,17,0,-Sheet2!P$2) -> 1720.6121 | Q15: =PV(Sheet1!$R93,17,0,-Sheet2!Q$2) -> 4546.793 | R15: =PV(Sheet1!$R93,17,0,-Sheet2!R$2) -> 3158.0842 | S15: =PV(Sheet1!$R93,17,0,-Sheet2!S$2) -> 2187.3515 | T15: =PV(Sheet1!$R93,17,0,-Sheet2!T$2) -> 2042.477 | U15: =PV(Sheet1!$R93,17,0,-Sheet2!U$2) -> 892.76699 | V15: =AVERAGE(P15:U15) -> 2424.6808 | W15: =PV(Sheet1!$R93,8,0,-Sheet1!K$21,0) -> 4.0152432 | X15: =PV(Sheet1!$R93,8,0,-Sheet1!L$21,0) -> 2.1324653 | Y15: =($V15/1000)/W15 -> 0.60386897 | Z15: =($V15/1000)/X15 -> 1.1370318 | AB15: =PV(Sheet1!$R93,17,0,-Sheet2!AB$2) -> 7562.6552 | AC15: =PV(Sheet1!$R93,17,0,-Sheet2!AC$2) -> 5702.9998 | AD15: =PV(Sheet1!$R93,17,0,-Sheet2!AD$2) -> 3488.5936 | AE15: =PV(Sheet1!$R93,17,0,-Sheet2!AE$2) -> 3870.2317 | AF15: =PV(Sheet1!$R93,17,0,-Sheet2!AF$2) -> 3057.4142 | AG15: =PV(Sheet1!$R93,17,0,-Sheet2!AG$2) -> 1360.6293 | AH15: =AVERAGE(AB15:AG15) -> 4173.754 | AI15: =PV(Sheet1!$R93,8,0,-Sheet1!K$19,0) -> 6.3655653 | AJ15: =($AH15/1000)/AI15 -> 0.65567688
... C17: =PV(Sheet1!$R95,17,0,-Sheet2!C$2) -> 4531.6788 | D17: =PV(Sheet1!$R95,17,0,-Sheet2!D$2) -> 4954.4302 | E17: =PV(Sheet1!$R95,17,0,-Sheet2!E$2) -> 3298.9148 | F17: =PV(Sheet1!$R95,17,0,-Sheet2!F$2) -> 2480.3529 | G17: =PV(Sheet1!$R95,17,0,-Sheet2!G$2) -> 1668.5107 | H17: =PV(Sheet1!$R95,17,0,-Sheet2!H$2) -> 718.33359 | I17: =AVERAGE(C17:H17) -> 2942.0368 | J17: =PV(Sheet1!R95,8,0,-Sheet1!K$23,0) -> 4.74596 | K17: =PV(Sheet1!$R95,8,0,-Sheet1!L$23,0) -> 2.5205434 | L17: =($I17/1000)/J17 -> 0.61990342 | M17: =($I17/1000)/K17 -> 1.1672232 | P17: =PV(Sheet1!$R95,17,0,-Sheet2!P$2) -> 1276.8892 | Q17: =PV(Sheet1!$R95,17,0,-Sheet2!Q$2) -> 3374.2359 | R17: =PV(Sheet1!$R95,17,0,-Sheet2!R$2) -> 2343.6565 | S17: =PV(Sheet1!$R95,17,0,-Sheet2!S$2) -> 1623.2628 | T17: =PV(Sheet1!$R95,17,0,-Sheet2!T$2) -> 1515.7495 | U17: =PV(Sheet1!$R95,17,0,-Sheet2!U$2) -> 662.53431 | V17: =AVERAGE(P17:U17) -> 1799.388 | W17: =PV(Sheet1!$R95,8,0,-Sheet1!K$21,0) -> 3.4894476 | X17: =PV(Sheet1!$R95,8,0,-Sheet1!L$21,0) -> 1.8532192 | Y17: =($V17/1000)/W17 -> 0.51566558 | Z17: =($V17/1000)/X17 -> 0.9709526 | AB17: =PV(Sheet1!$R95,17,0,-Sheet2!AB$2) -> 5612.3475 | AC17: =PV(Sheet1!$R95,17,0,-Sheet2!AC$2) -> 4232.2723 | AD17: =PV(Sheet1!$R95,17,0,-Sheet2!AD$2) -> 2588.9319 | AE17: =PV(Sheet1!$R95,17,0,-Sheet2!AE$2) -> 2872.1507 | AF17: =PV(Sheet1!$R95,17,0,-Sheet2!AF$2) -> 2268.9479 | AG17: =PV(Sheet1!$R95,17,0,-Sheet2!AG$2) -> 1009.7412 | AH17: =AVERAGE(AB17:AG17) -> 3097.3986 | AI17: =PV(Sheet1!$R95,8,0,-Sheet1!K$19,0) -> 5.5319953 | AJ17: =($AH17/1000)/AI17 -> 0.55990623

Sheet Sheet3
E2: =Sheet1!R33/1000 -> 1.3633032 | F2: =Sheet1!S33/1000 -> 4.493338 | G2: =Sheet1!T33/1000 -> 2.7061925 | H2: =Sheet1!U33/1000 -> 5.1449408 | I2: =Sheet1!V33/1000 -> 12.556481 | J2: =Sheet1!W33/1000 -> 2.4848101 | K2: =Sheet1!X33/1000 -> 4.791511 | O2: Bradfield Vaucluse | P2: 1.3633032 | Q2: 4.493338 | R2: 2.7061925 | S2: 5.1449408 | T2: 12.556481 | U2: 2.4848101 | V2: 4.791511
E3: =Sheet1!R34/1000 -> 3.9136779 | F3: =Sheet1!S34/1000 -> 7.3328203 | G3: =Sheet1!T34/1000 -> 5.0882753 | H3: =Sheet1!U34/1000 -> 1.6336266 | I3: =Sheet1!V34/1000 -> 2.1272617 | J3: =Sheet1!W34/1000 -> 1.199575 | K3: =Sheet1!X34/1000 -> 3.5492061 | O3: Bradfield Sydenham | P3: 3.9136779 | Q3: 7.3328203 | R3: 5.0882753 | S3: 1.6336266 | T3: 2.1272617 | U3: 1.199575 | V3: 3.5492061
E4: =Sheet1!R35/1000 -> 4.6446225 | F4: =Sheet1!S35/1000 -> 10.689911 | G4: =Sheet1!T35/1000 -> 7.3153007 | H4: =Sheet1!U35/1000 -> 2.7281085 | I4: =Sheet1!V35/1000 -> 4.7633476 | J4: =Sheet1!W35/1000 -> 2.0928873 | K4: =Sheet1!X35/1000 -> 5.372363 | O4: Bradfield Malabar | P4: 4.6446225 | Q4: 10.689911 | R4: 7.3153007 | S4: 2.7281085 | T4: 4.7633476 | U4: 2.0928873 | V4: 5.372363
E5: =Sheet1!R36/1000 -> 5.6112383 | F5: =Sheet1!S36/1000 -> 9.2698363 | G5: =Sheet1!T36/1000 -> 6.1325127 | H5: =Sheet1!U36/1000 -> 2.6869718 | I5: =Sheet1!V36/1000 -> 2.807444 | J5: =Sheet1!W36/1000 -> 1.6196524 | K5: =Sheet1!X36/1000 -> 4.6879426 | O5: Bradfield Sydenham & Malabar | P5: 5.6112383 | Q5: 9.2698363 | R5: 6.1325127 | S5: 2.6869718 | T5: 2.807444 | U5: 1.6196524 | V5: 4.6879426
E6: =Sheet1!R37/1000 -> 1.6975603 | F6: =Sheet1!S37/1000 -> 1.937016 | G6: =Sheet1!T37/1000 -> 1.0442374 | H6: =Sheet1!U37/1000 -> 1.0533452 | I6: =Sheet1!V37/1000 -> 0.68018234 | J6: =Sheet1!W37/1000 -> 0.42007733 | K6: =Sheet1!X37/1000 -> 1.1387364 | O6: Marginal Malabar | P6: 1.6975603 | Q6: 1.937016 | R6: 1.0442374 | S6: 1.0533452 | T6: 0.68018234 | U6: 0.42007733 | V6: 1.1387364
E7: =Sheet1!R38/1000 -> 2.9939321 | F7: =Sheet1!S38/1000 -> 8.9281558 | G7: =Sheet1!T38/1000 -> 6.6964488 | H7: =Sheet1!U38/1000 -> 2.9189101 | I7: =Sheet1!V38/1000 -> 10.226748 | J7: =Sheet1!W38/1000 -> 3.3802808 | K7: =Sheet1!X38/1000 -> 5.8574125 | O7: Bradfield Full | P7: 2.9939321 | Q7: 8.9281558 | R7: 6.6964488 | S7: 2.9189101 | T7: 10.226748 | U7: 3.3802808 | V7: 5.8574125
E8: =Sheet1!R39/1000 -> -2.6173062 | F8: =Sheet1!S39/1000 -> -0.34168045 | G8: =Sheet1!T39/1000 -> 0.56393606 | H8: =Sheet1!U39/1000 -> 0.23193836 | I8: =Sheet1!V39/1000 -> 7.4193036 | J8: =Sheet1!W39/1000 -> 1.7606284 | K8: =Sheet1!X39/1000 -> 1.16947 | O8: Marginal Full | P8: -2.6173062 | Q8: -0.34168045 | R8: 0.56393606 | S8: 0.23193836 | T8: 7.4193036 | U8: 1.7606284 | V8: 1.16947
E9: =Sheet1!R40/1000 -> 1.8178623 | F9: =Sheet1!S40/1000 -> 3.430126 | G9: =Sheet1!T40/1000 -> 2.2060848 | H9: =Sheet1!U40/1000 -> 1.016139 | I9: =Sheet1!V40/1000 -> 0.98692677 | J9: =Sheet1!W40/1000 -> 0.55254343 | K9: =Sheet1!X40/1000 -> 1.6682804 | O9: 1974 | P9: 1.8178623 | Q9: 3.430126 | R9: 2.2060848 | S9: 1.016139 | T9: 0.98692677 | U9: 0.55254343 | V9: 1.6682804
E10: =Sheet1!R41/1000 -> 1.0357336 | F10: =Sheet1!S41/1000 -> 2.3436981 | G10: =Sheet1!T41/1000 -> 1.4877728 | H10: =Sheet1!U41/1000 -> 1.9535831 | I10: =Sheet1!V41/1000 -> 3.2494232 | J10: =Sheet1!W41/1000 -> 0.8242232 | K10: =Sheet1!X41/1000 -> 1.815739 | O10: 2001 | P10: 1.0357336 | Q10: 2.3436981 | R10: 1.4877728 | S10: 1.9535831 | T10: 3.2494232 | U10: 0.8242232 | V10: 1.815739
E11: =Sheet1!R42/1000 -> 10.829332 | F11: =Sheet1!S42/1000 -> 12.7543 | G11: =Sheet1!T42/1000 -> 8.5611197 | H11: =Sheet1!U42/1000 -> 2.8148864 | I11: =Sheet1!V42/1000 -> 5.3219585 | J11: =Sheet1!W42/1000 -> 1.9111873 | K11: =Sheet1!X42/1000 -> 7.0321308 | O11: 2056 Stage 1 | P11: 10.829332 | Q11: 12.7543 | R11: 8.5611197 | S11: 2.8148864 | T11: 5.3219585 | U11: 1.9111873 | V11: 7.0321308
E12: =Sheet1!R43/1000 -> 12.40922 | F12: =Sheet1!S43/1000 -> 16.382865 | G12: =Sheet1!T43/1000 -> 11.396363 | H12: =Sheet1!U43/1000 -> 3.9775078 | I12: =Sheet1!V43/1000 -> 6.8985982 | J12: =Sheet1!W43/1000 -> 2.5772956 | K12: =Sheet1!X43/1000 -> 8.9403082 | O12: 2056 Stage 1 and 2 | P12: 12.40922 | Q12: 16.382865 | R12: 11.396363 | S12: 3.9775078 | T12: 6.8985982 | U12: 2.5772956 | V12: 8.9403082
E13: =Sheet1!R44/1000 -> 1.579887 | F13: =Sheet1!S44/1000 -> 3.6285651 | G13: =Sheet1!T44/1000 -> 2.8352431 | H13: =Sheet1!U44/1000 -> 1.1626214 | I13: =Sheet1!V44/1000 -> 1.5766397 | J13: =Sheet1!W44/1000 -> 0.66610833 | K13: =Sheet1!X44/1000 -> 1.9081775 | O13: Marginal Stage 2 Metro | P13: 1.579887 | Q13: 3.6285651 | R13: 2.8352431 | S13: 1.1626214 | T13: 1.5766397 | U13: 0.66610833 | V13: 1.9081775
E14: =Sheet1!R45/1000 -> 0.10131772 | F14: =Sheet1!S45/1000 -> 0.62474051 | G14: =Sheet1!T45/1000 -> 0.73958996 | H14: =Sheet1!U45/1000 -> 0.14023651 | I14: =Sheet1!V45/1000 -> 0.34493559 | J14: =Sheet1!W45/1000 -> 0.23349705 | K14: =Sheet1!X45/1000 -> 0.36405289 | O14: Light Rail Extension | P14: 0.10131772 | Q14: 0.62474051 | R14: 0.73958996 | S14: 0.14023651 | T14: 0.34493559 | U14: 0.23349705 | V14: 0.36405289
E15: =Sheet1!R46/1000 -> 0.74030982 | F15: =Sheet1!S46/1000 -> 1.6117446 | G15: =Sheet1!T46/1000 -> 1.1665369 | H15: =Sheet1!U46/1000 -> 0.46440667 | I15: =Sheet1!V46/1000 -> 1.1811803 | J15: =Sheet1!W46/1000 -> 0.43181044 | K15: =Sheet1!X46/1000 -> 0.93266478 | O15: Light Rail with Oxford Street Rail | P15: 0.74030982 | Q15: 1.6117446 | R15: 1.1665369 | S15: 0.46440667 | T15: 1.1811803 | U15: 0.43181044 | V15: 0.93266478
E16: =Sheet1!R47/1000 -> 0.6389921 | F16: =Sheet1!S47/1000 -> 0.98700407 | G16: =Sheet1!T47/1000 -> 0.4269469 | H16: =Sheet1!U47/1000 -> 0.32417016 | I16: =Sheet1!V47/1000 -> 0.83624473 | J16: =Sheet1!W47/1000 -> 0.19831339 | K16: =Sheet1!X47/1000 -> 0.56861189 | O16: Marginal Oxford Street | P16: 0.6389921 | Q16: 0.98700407 | R16: 0.4269469 | S16: 0.32417016 | T16: 0.83624473 | U16: 0.19831339 | V16: 0.56861189
E17: =Sheet1!R48/1000 -> 19.119812 | F17: =Sheet1!S48/1000 -> 14.418254 | G17: =Sheet1!T48/1000 -> 8.8198196 | H17: =Sheet1!U48/1000 -> 9.7846724 | I17: =Sheet1!V48/1000 -> 7.7297169 | J17: =Sheet1!W48/1000 -> 3.4399264 | K17: =Sheet1!X48/1000 -> 10.552034 | O17: Extensive Eastern Suburbs Lightrail | P17: 19.119812 | Q17: 14.418254 | R17: 8.8198196 | S17: 9.7846724 | T17: 7.7297169 | U17: 3.4399264 | V17: 10.552034
E18: =Sheet1!R49/1000 -> 18.379502 | F18: =Sheet1!S49/1000 -> 12.806509 | G18: =Sheet1!T49/1000 -> 7.6532827 | H18: =Sheet1!U49/1000 -> 9.3202657 | I18: =Sheet1!V49/1000 -> 6.5485366 | J18: =Sheet1!W49/1000 -> 3.0081159 | K18: =Sheet1!X49/1000 -> 9.6193688 | O18: Marginal Extensive Lightrail | P18: 18.379502 | Q18: 12.806509 | R18: 7.6532827 | S18: 9.3202657 | T18: 6.5485366 | U18: 3.0081159 | V18: 9.6193688
E19: =Sheet1!R50/1000 -> 4.3500304 | F19: =Sheet1!S50/1000 -> 11.495146 | G19: =Sheet1!T50/1000 -> 7.9842296 | H19: =Sheet1!U50/1000 -> 5.5300352 | I19: =Sheet1!V50/1000 -> 5.1637653 | J19: =Sheet1!W50/1000 -> 2.2570825 | K19: =Sheet1!X50/1000 -> 6.1300482 | O19: Combination Proposal | P19: 4.3500304 | Q19: 11.495146 | R19: 7.9842296 | S19: 5.5300352 | T19: 5.1637653 | U19: 2.2570825 | V19: 6.1300482
E20: =Sheet1!R51/1000 -> 5.8330178 | F20: =Sheet1!S51/1000 -> 12.036731 | G20: =Sheet1!T51/1000 -> 7.2019771 | H20: =Sheet1!U51/1000 -> 5.8572579 | I20: =Sheet1!V51/1000 -> 8.2383789 | J20: =Sheet1!W51/1000 -> 2.7895411 | K20: =Sheet1!X51/1000 -> 6.9928174 | O20: Combination Proposal Metro | P20: 5.8330178 | Q20: 12.036731 | R20: 7.2019771 | S20: 5.8572579 | T20: 8.2383789 | U20: 2.7895411 | V20: 6.9928174
E21: =Sheet1!R52/1000 -> 15.438254 | F21: =Sheet1!S52/1000 -> 16.878458 | G21: =Sheet1!T52/1000 -> 11.238547 | H21: =Sheet1!U52/1000 -> 8.449919 | I21: =Sheet1!V52/1000 -> 5.684183 | J21: =Sheet1!W52/1000 -> 2.4471762 | K21: =Sheet1!X52/1000 -> 10.022756 | O21: Alternative 2056 Metro | P21: 15.438254 | Q21: 16.878458 | R21: 11.238547 | S21: 8.449919 | T21: 5.684183 | U21: 2.4471762 | V21: 10.022756
E22: =Sheet1!R53/1000 -> 15.608507 | F22: =Sheet1!S53/1000 -> 17.252746 | G22: =Sheet1!T53/1000 -> 11.370664 | H22: =Sheet1!U53/1000 -> 8.6322173 | I22: =Sheet1!V53/1000 -> 5.9549238 | J22: =Sheet1!W53/1000 -> 2.4924076 | K22: =Sheet1!X53/1000 -> 10.218578 | O22: Alternative 2056 Metro Coogee | P22: 15.608507 | Q22: 17.252746 | R22: 11.370664 | S22: 8.6322173 | T22: 5.9549238 | U22: 2.4924076 | V22: 10.218578
